Workbook

Sheet 1310
A3: =104+88+36 -> 228
A5: MOIS DE OCTOBRE
A6: DESCRIPTION | B6: 45943
B7: STOCK INT | C7: RECEPTION | D7: UNITE | E7: SORTIER | F7: PRIX | G7: VALEUR | H7: STOCK
A8: DOUBLE FACE | B8: 86 | D8: ROULEAU | E8: 6 | F8: 230.62 | G8: =E8*F8 -> 1383.72 | H8: =B8-E8 -> 80
A9: SCOTCHE | B9: 78 | D9: ROULEAU | F9: 91.2 | G9: =E9*F9 -> 0 | H9: =B9-E9 -> 78
A10: FEUILLARD N12 | B10: 238 | D10: ROULEAU | F10: 3500 | G10: =E10*F10 -> 0 | H10: =B10-E10 -> 238
A11: FEUILLARD N5 | B11: 25 | D11: ROULEAU | F11: 3300 | G11: =E11*F11 -> 0 | H11: =B11-E11 -> 25
A12: CELOPHANE 7 | B12: 65 | D12: ROULEAU | E12: 1 | F12: 1554.62 | G12: =E12*F12 -> 1554.62 | H12: =B12-E12 -> 64
A13: CELOPHANE 16 | B13: 384 | C13: 2220 | D13: KG | F13: 210 | G13: =E13*F13 -> 0 | H13: =B13-E13+C13 -> 2604
A14: CELOPHANE 25 | B14: 24 | D14: KG | G14: =E14*F14 -> 0 | H14: =B14-E14 -> 24
A15: COLLE | B15: 1620 | D15: KG | E15: 30 | F15: 290 | G15: =E15*F15 -> 8700 | H15: =B15-E15 -> 1590
A16: SEL | B16: 750 | C16: 2450 | D16: KG | E16: 50 | F16: 49.5 | G16: =E16*F16 -> 2475 | H16: =B16-E16+C16 -> 3150
A17: BORAX | B17: 525 | D17: KG | F17: 285 | G17: =E17*F17 -> 0 | H17: =B17-E17 -> 525
A18: AMIDON | B18: 24000 | C18: 25000 | D18: KG | E18: =50*25 -> 1250 | F18: 93 | G18: =E18*F18 -> 116250 | H18: =B18-E18+C18 -> 47750
A19: SOUDE | B19: 3000 | D19: KG | E19: 28 | F19: 67.23 | G19: =E19*F19 -> 1882.44 | H19: =B19-E19 -> 2972
A20: ANALYFLIX | B20: 375 | D20: L | F20: 480 | G20: =E20*F20 -> 0 | H20: =B20-E20 -> 375
A21: FIL RECUIT | B21: 1 | C21: 30 | D21: ROULEAU | G21: =E21*F21 -> 0 | H21: =B21-E21+C21 -> 31
A43: TOTAL | E43: =SUM(E8:E41) -> 1365

Sheet 1410
A2: DESCRIPTION | B2: 45944
B3: STOCK INT | C3: RECEPTION | D3: UNITE | E3: SORTIER | F3: PRIX | G3: VALEUR | H3: STOCK
A4: DOUBLE FACE | B4: =+'1310'!H8 -> 80 | D4: ROULEAU | E4: 3 | F4: 230.62 | G4: =E4*F4 -> 691.86 | H4: =B4-E4 -> 77
A5: SCOTCHE | B5: =+'1310'!H9 -> 78 | D5: ROULEAU | F5: 91.2 | G5: =E5*F5 -> 0 | H5: =B5-E5 -> 78
A6: FEUILLARD N12 | B6: =+'1310'!H10 -> 238 | D6: ROULEAU | E6: 3 | F6: 3500 | G6: =E6*F6 -> 10500 | H6: =B6-E6 -> 235
A7: FEUILLARD N5 | B7: =+'1310'!H11 -> 25 | D7: ROULEAU | E7: 1 | F7: 3300 | G7: =E7*F7 -> 3300 | H7: =B7-E7 -> 24
A8: CELOPHANE 7 | B8: =+'1310'!H12 -> 64 | D8: ROULEAU | E8: 1 | F8: 1554.62 | G8: =E8*F8 -> 1554.62 | H8: =B8-E8 -> 63
A9: CELOPHANE 16 | B9: =+'1310'!H13 -> 2604 | D9: KG | E9: 32 | F9: 210 | G9: =E9*F9 -> 6720 | H9: =B9-E9 -> 2572
A10: CELOPHANE 25 | B10: =+'1310'!H14 -> 24 | D10: KG | G10: =E10*F10 -> 0 | H10: =B10-E10 -> 24
A11: COLLE | B11: =+'1310'!H15 -> 1590 | D11: KG | E11: 30 | F11: 290 | G11: =E11*F11 -> 8700 | H11: =B11-E11 -> 1560
A12: SEL | B12: =+'1310'!H16 -> 3150 | D12: KG | E12: 75 | F12: 49.5 | G12: =E12*F12 -> 3712.5 | H12: =B12-E12 -> 3075
A13: BORAX | B13: =+'1310'!H17 -> 525 | D13: KG | F13: 285 | G13: =E13*F13 -> 0 | H13: =B13-E13 -> 525
A14: AMIDON | B14: =+'1310'!H18 -> 47750 | D14: KG | E14: 750 | F14: 93 | G14: =E14*F14 -> 69750 | H14: =B14-E14 -> 47000
A15: SOUDE | B15: =+'1310'!H19 -> 2972 | D15: KG | E15: 42 | F15: 67.23 | G15: =E15*F15 -> 2823.66 | H15: =B15-E15 -> 2930
A16: ANALYFLIX | B16: =+'1310'!H20 -> 375 | D16: L | F16: 480 | G16: =E16*F16 -> 0 | H16: =B16-E16 -> 375
A17: FIL RECUIT | B17: =+'1310'!H21 -> 31 | D17: ROULEAU | G17: =E17*F17 -> 0 | H17: =B17-E17 -> 31
A39: TOTAL | E39: =SUM(E4:E37) -> 937

Sheet 1510
A2: DESCRIPTION | B2: 45945
B3: STOCK INT | C3: RECEPTION | D3: UNITE | E3: SORTIER | F3: PRIX | G3: VALEUR | H3: STOCK
A4: DOUBLE FACE | B4: =+'1410'!H4 -> 77 | D4: ROULEAU | E4: 3 | F4: 230.62 | G4: =E4*F4 -> 691.86 | H4: =B4-E4 -> 74
A5: SCOTCHE | B5: =+'1410'!H5 -> 78 | D5: ROULEAU | F5: 91.2 | G5: =E5*F5 -> 0 | H5: =B5-E5 -> 78
A6: FEUILLARD N12 | B6: =+'1410'!H6 -> 235 | D6: ROULEAU | E6: 2 | F6: 3500 | G6: =E6*F6 -> 7000 | H6: =B6-E6 -> 233
A7: FEUILLARD N5 | B7: =+'1410'!H7 -> 24 | D7: ROULEAU | E7: 2 | F7: 3300 | G7: =E7*F7 -> 6600 | H7: =B7-E7 -> 22
A8: CELOPHANE 7 | B8: =+'1410'!H8 -> 63 | D8: ROULEAU | E8: 4 | F8: 1554.62 | G8: =E8*F8 -> 6218.48 | H8: =B8-E8 -> 59
A9: CELOPHANE 16 | B9: =+'1410'!H9 -> 2572 | D9: KG | E9: 16 | F9: 210 | G9: =E9*F9 -> 3360 | H9: =B9-E9 -> 2556
A10: CELOPHANE 25 | B10: =+'1410'!H10 -> 24 | D10: KG | G10: =E10*F10 -> 0 | H10: =B10-E10 -> 24
A11: COLLE | B11: =+'1410'!H11 -> 1560 | D11: KG | E11: 60 | F11: 290 | G11: =E11*F11 -> 17400 | H11: =B11-E11 -> 1500
A12: SEL | B12: =+'1410'!H12 -> 3075 | D12: KG | E12: 50 | F12: 49.5 | G12: =E12*F12 -> 2475 | H12: =B12-E12 -> 3025
A13: BORAX | B13: =+'1410'!H13 -> 525 | D13: KG | F13: 285 | G13: =E13*F13 -> 0 | H13: =B13-E13 -> 525
A14: AMIDON | B14: =+'1410'!H14 -> 47000 | D14: KG | E14: 750 | F14: 93 | G14: =E14*F14 -> 69750 | H14: =B14-E14 -> 46250
A15: SOUDE | B15: =+'1410'!H15 -> 2930 | D15: KG | E15: 56 | F15: 67.23 | G15: =E15*F15 -> 3764.88 | H15: =B15-E15 -> 2874
A16: ANALYFLIX | B16: =+'1410'!H16 -> 375 | D16: L | F16: 480 | G16: =E16*F16 -> 0 | H16: =B16-E16 -> 375
A17: FIL RECUIT | B17: =+'1410'!H17 -> 31 | D17: ROULEAU | G17: =E17*F17 -> 0 | H17: =B17-E17 -> 31
A39: TOTAL | E39: =SUM(E4:E37) -> 943

Sheet 1610
A2: DESCRIPTION | B2: 45946
B3: STOCK INT | C3: RECEPTION | D3: UNITE | E3: SORTIER | F3: PRIX | G3: VALEUR | H3: STOCK
A4: DOUBLE FACE | B4: =+'1510'!H4 -> 74 | D4: ROULEAU | E4: 3 | F4: 230.62 | G4: =E4*F4 -> 691.86 | H4: =B4-E4 -> 71
A5: SCOTCHE | B5: =+'1510'!H5 -> 78 | D5: ROULEAU | F5: 91.2 | G5: =E5*F5 -> 0 | H5: =B5-E5 -> 78
A6: FEUILLARD N12 | B6: =+'1510'!H6 -> 233 | D6: ROULEAU | F6: 3500 | G6: =E6*F6 -> 0 | H6: =B6-E6 -> 233
A7: FEUILLARD N5 | B7: =+'1510'!H7 -> 22 | D7: ROULEAU | E7: 1 | F7: 3300 | G7: =E7*F7 -> 3300 | H7: =B7-E7 -> 21
A8: CELOPHANE 7 | B8: =+'1510'!H8 -> 59 | D8: ROULEAU | E8: 4 | F8: 1554.62 | G8: =E8*F8 -> 6218.48 | H8: =B8-E8 -> 55
A9: CELOPHANE 16 | B9: =+'1510'!H9 -> 2556 | D9: KG | F9: 210 | G9: =E9*F9 -> 0 | H9: =B9-E9 -> 2556
A10: CELOPHANE 25 | B10: =+'1510'!H10 -> 24 | D10: KG | G10: =E10*F10 -> 0 | H10: =B10-E10 -> 24
A11: COLLE | B11: =+'1510'!H11 -> 1500 | D11: KG | E11: 30 | F11: 290 | G11: =E11*F11 -> 8700 | H11: =B11-E11 -> 1470
A12: SEL | B12: =+'1510'!H12 -> 3025 | D12: KG | F12: 49.5 | G12: =E12*F12 -> 0 | H12: =B12-E12 -> 3025
A13: BORAX | B13: =+'1510'!H13 -> 525 | D13: KG | F13: 285 | G13: =E13*F13 -> 0 | H13: =B13-E13 -> 525
A14: AMIDON | B14: =+'1510'!H14 -> 46250 | D14: KG | E14: 1000 | F14: 93 | G14: =E14*F14 -> 93000 | H14: =B14-E14 -> 45250
A15: SOUDE | B15: =+'1510'!H15 -> 2874 | D15: KG | E15: 42 | F15: 67.23 | G15: =E15*F15 -> 2823.66 | H15: =B15-E15 -> 2832
A16: ANALYFLIX | B16: =+'1510'!H16 -> 375 | D16: L | F16: 480 | G16: =E16*F16 -> 0 | H16: =B16-E16 -> 375
A17: FIL RECUIT | B17: =+'1510'!H17 -> 31 | D17: ROULEAU | G17: =E17*F17 -> 0 | H17: =B17-E17 -> 31
A39: TOTAL | E39: =SUM(E4:E37) -> 1080

Sheet 1910
A2: DESCRIPTION | B2: 45949
B3: STOCK INT | C3: RECEPTION | D3: UNITE | E3: SORTIER | F3: PRIX | G3: VALEUR | H3: STOCK
A4: DOUBLE FACE | B4: =+'1610'!H4 -> 71 | D4: ROULEAU | E4: 3 | F4: 230.62 | G4: =E4*F4 -> 691.86 | H4: =B4-E4 -> 68
A5: SCOTCHE | B5: =+'1610'!H5 -> 78 | D5: ROULEAU | E5: 3 | F5: 91.2 | G5: =E5*F5 -> 273.6 | H5: =B5-E5 -> 75
A6: FEUILLARD N12 | B6: =+'1610'!H6 -> 233 | D6: ROULEAU | E6: 2 | F6: 3500 | G6: =E6*F6 -> 7000 | H6: =B6-E6 -> 231
A7: FEUILLARD N5 | B7: =+'1610'!H7 -> 21 | D7: ROULEAU | E7: 1 | F7: 3300 | G7: =E7*F7 -> 3300 | H7: =B7-E7 -> 20
A8: CELOPHANE 7 | B8: =+'1610'!H8 -> 55 | D8: ROULEAU | E8: 5 | F8: 1554.62 | G8: =E8*F8 -> 7773.1 | H8: =B8-E8 -> 50
A9: CELOPHANE 16 | B9: =+'1610'!H9 -> 2556 | D9: KG | E9: 32 | F9: 210 | G9: =E9*F9 -> 6720 | H9: =B9-E9 -> 2524
A10: CELOPHANE 25 | B10: =+'1610'!H10 -> 24 | D10: KG | G10: =E10*F10 -> 0 | H10: =B10-E10 -> 24
A11: COLLE | B11: =+'1610'!H11 -> 1470 | D11: KG | E11: 30 | F11: 290 | G11: =E11*F11 -> 8700 | H11: =B11-E11 -> 1440
A12: SEL | B12: =+'1610'!H12 -> 3025 | D12: KG | E12: 100 | F12: 49.5 | G12: =E12*F12 -> 4950 | H12: =B12-E12 -> 2925
A13: BORAX | B13: =+'1610'!H13 -> 525 | D13: KG | E13: 50 | F13: 285 | G13: =E13*F13 -> 14250 | H13: =B13-E13 -> 475
A14: AMIDON | B14: =+'1610'!H14 -> 45250 | D14: KG | E14: 1500 | F14: 93 | G14: =E14*F14 -> 139500 | H14: =B14-E14 -> 43750
A15: SOUDE | B15: =+'1610'!H15 -> 2832 | D15: KG | E15: 84 | F15: 67.23 | G15: =E15*F15 -> 5647.32 | H15: =B15-E15 -> 2748
A16: ANALYFLIX | B16: =+'1610'!H16 -> 375 | D16: L | F16: 480 | G16: =E16*F16 -> 0 | H16: =B16-E16 -> 375
A17: FIL RECUIT | B17: =+'1610'!H17 -> 31 | D17: ROULEAU | G17: =E17*F17 -> 0 | H17: =B17-E17 -> 31
A39: TOTAL | E39: =SUM(E4:E37) -> 1810

Sheet 2010
A2: DESCRIPTION | B2: 45950
B3: STOCK INT | C3: RECEPTION | D3: UNITE | E3: SORTIER | F3: PRIX | G3: VALEUR | H3: STOCK
A4: DOUBLE FACE | B4: =+'1910'!H4 -> 68 | D4: ROULEAU | E4: 3 | F4: 230.62 | G4: =E4*F4 -> 691.86 | H4: =B4-E4 -> 65
A5: SCOTCHE | B5: =+'1910'!H5 -> 75 | D5: ROULEAU | F5: 91.2 | G5: =E5*F5 -> 0 | H5: =B5-E5 -> 75
A6: FEUILLARD N12 | B6: =+'1910'!H6 -> 231 | D6: ROULEAU | E6: 2 | F6: 3500 | G6: =E6*F6 -> 7000 | H6: =B6-E6 -> 229
A7: FEUILLARD N5 | B7: =+'1910'!H7 -> 20 | D7: ROULEAU | E7: 1 | F7: 3300 | G7: =E7*F7 -> 3300 | H7: =B7-E7 -> 19
A8: CELOPHANE 7 | B8: =+'1910'!H8 -> 50 | D8: ROULEAU | F8: 1554.62 | G8: =E8*F8 -> 0 | H8: =B8-E8 -> 50
A9: CELOPHANE 16 | B9: =+'1910'!H9 -> 2524 | D9: KG | E9: 16 | F9: 210 | G9: =E9*F9 -> 3360 | H9: =B9-E9 -> 2508
A10: CELOPHANE 25 | B10: =+'1910'!H10 -> 24 | D10: KG | G10: =E10*F10 -> 0 | H10: =B10-E10 -> 24
A11: COLLE | B11: =+'1910'!H11 -> 1440 | D11: KG | E11: 30 | F11: 290 | G11: =E11*F11 -> 8700 | H11: =B11-E11 -> 1410
A12: SEL | B12: =+'1910'!H12 -> 2925 | D12: KG | F12: 49.5 | G12: =E12*F12 -> 0 | H12: =B12-E12 -> 2925
A13: BORAX | B13: =+'1910'!H13 -> 475 | D13: KG | F13: 285 | G13: =E13*F13 -> 0 | H13: =B13-E13 -> 475
A14: AMIDON | B14: =+'1910'!H14 -> 43750 | D14: KG | E14: 1050 | F14: 93 | G14: =E14*F14 -> 97650 | H14: =B14-E14 -> 42700
A15: SOUDE | B15: =+'1910'!H15 -> 2748 | D15: KG | E15: 42 | F15: 67.23 | G15: =E15*F15 -> 2823.66 | H15: =B15-E15 -> 2706
A16: ANALYFLIX | B16: =+'1910'!H16 -> 375 | D16: L | F16: 480 | G16: =E16*F16 -> 0 | H16: =B16-E16 -> 375
A17: FIL RECUIT | B17: =+'1910'!H17 -> 31 | D17: ROULEAU | G17: =E17*F17 -> 0 | H17: =B17-E17 -> 31
A39: TOTAL | E39: =SUM(E4:E37) -> 1144

Sheet 2110
A2: DESCRIPTION | B2: 45951
B3: STOCK INT | C3: RECEPTION | D3: UNITE | E3: SORTIER | F3: PRIX | G3: VALEUR | H3: STOCK
A4: DOUBLE FACE | B4: =+'2010'!H4 -> 65 | D4: ROULEAU | E4: 6 | F4: 230.62 | G4: =E4*F4 -> 1383.72 | H4: =B4-E4 -> 59
A5: SCOTCHE | B5: =+'2010'!H5 -> 75 | D5: ROULEAU | F5: 91.2 | G5: =E5*F5 -> 0 | H5: =B5-E5 -> 75
A6: FEUILLARD N12 | B6: =+'2010'!H6 -> 229 | D6: ROULEAU | E6: 2 | F6: 3500 | G6: =E6*F6 -> 7000 | H6: =B6-E6 -> 227
A7: FEUILLARD N5 | B7: =+'2010'!H7 -> 19 | D7: ROULEAU | E7: 2 | F7: 3300 | G7: =E7*F7 -> 6600 | H7: =B7-E7 -> 17
A8: CELOPHANE 7 | B8: =+'2010'!H8 -> 50 | D8: ROULEAU | F8: 1554.62 | G8: =E8*F8 -> 0 | H8: =B8-E8 -> 50
A9: CELOPHANE 16 | B9: =+'2010'!H9 -> 2508 | D9: KG | F9: 210 | G9: =E9*F9 -> 0 | H9: =B9-E9 -> 2508
A10: CELOPHANE 25 | B10: =+'2010'!H10 -> 24 | D10: KG | G10: =E10*F10 -> 0 | H10: =B10-E10 -> 24
A11: COLLE | B11: =+'2010'!H11 -> 1410 | D11: KG | E11: 30 | F11: 290 | G11: =E11*F11 -> 8700 | H11: =B11-E11 -> 1380
A12: SEL | B12: =+'2010'!H12 -> 2925 | D12: KG | E12: 50 | F12: 49.5 | G12: =E12*F12 -> 2475 | H12: =B12-E12 -> 2875
A13: BORAX | B13: =+'2010'!H13 -> 475 | D13: KG | F13: 285 | G13: =E13*F13 -> 0 | H13: =B13-E13 -> 475
A14: AMIDON | B14: =+'2010'!H14 -> 42700 | D14: KG | E14: 1500 | F14: 93 | G14: =E14*F14 -> 139500 | H14: =B14-E14 -> 41200
A15: SOUDE | B15: =+'2010'!H15 -> 2706 | D15: KG | E15: 70 | F15: 67.23 | G15: =E15*F15 -> 4706.1 | H15: =B15-E15 -> 2636
A16: ANALYFLIX | B16: =+'2010'!H16 -> 375 | D16: L | F16: 480 | G16: =E16*F16 -> 0 | H16: =B16-E16 -> 375
A17: FIL RECUIT | B17: =+'2010'!H17 -> 31 | D17: ROULEAU | G17: =E17*F17 -> 0 | H17: =B17-E17 -> 31
A39: TOTAL | E39: =SUM(E4:E37) -> 1660

Sheet 2210
A2: DESCRIPTION | B2: 45952
B3: STOCK INT | C3: RECEPTION | D3: UNITE | E3: SORTIER | F3: PRIX | G3: VALEUR | H3: STOCK
A4: DOUBLE FACE | B4: =+'2110'!H4 -> 59 | D4: ROULEAU | F4: 230.62 | G4: =E4*F4 -> 0 | H4: =B4-E4 -> 59
A5: SCOTCHE | B5: =+'2110'!H5 -> 75 | D5: ROULEAU | F5: 91.2 | G5: =E5*F5 -> 0 | H5: =B5-E5 -> 75
A6: FEUILLARD N12 | B6: =+'2110'!H6 -> 227 | D6: ROULEAU | E6: 2 | F6: 3500 | G6: =E6*F6 -> 7000 | H6: =B6-E6 -> 225
A7: FEUILLARD N5 | B7: =+'2110'!H7 -> 17 | D7: ROULEAU | F7: 3300 | G7: =E7*F7 -> 0 | H7: =B7-E7 -> 17
A8: CELOPHANE 7 | B8: =+'2110'!H8 -> 50 | D8: ROULEAU | E8: 1 | F8: 1554.62 | G8: =E8*F8 -> 1554.62 | H8: =B8-E8 -> 49
A9: CELOPHANE 16 | B9: =+'2110'!H9 -> 2508 | D9: KG | E9: 32 | F9: 210 | G9: =E9*F9 -> 6720 | H9: =B9-E9 -> 2476
A10: CELOPHANE 25 | B10: =+'2110'!H10 -> 24 | D10: KG | G10: =E10*F10 -> 0 | H10: =B10-E10 -> 24
A11: COLLE | B11: =+'2110'!H11 -> 1380 | D11: KG | E11: 60 | F11: 290 | G11: =E11*F11 -> 17400 | H11: =B11-E11 -> 1320
A12: SEL | B12: =+'2110'!H12 -> 2875 | D12: KG | F12: 49.5 | G12: =E12*F12 -> 0 | H12: =B12-E12 -> 2875
A13: BORAX | B13: =+'2110'!H13 -> 475 | D13: KG | F13: 285 | G13: =E13*F13 -> 0 | H13: =B13-E13 -> 475
A14: AMIDON | B14: =+'2110'!H14 -> 41200 | D14: KG | E14: 1500 | F14: 93 | G14: =E14*F14 -> 139500 | H14: =B14-E14 -> 39700 | J14: =1320/30 -> 44
A15: SOUDE | B15: =+'2110'!H15 -> 2636 | D15: KG | E15: 56 | F15: 67.23 | G15: =E15*F15 -> 3764.88 | H15: =B15-E15 -> 2580
A16: ANALYFLIX | B16: =+'2110'!H16 -> 375 | D16: L | E16: 25 | F16: 480 | G16: =E16*F16 -> 12000 | H16: =B16-E16 -> 350
A17: FIL RECUIT | B17: =+'2110'!H17 -> 31 | D17: ROULEAU | G17: =E17*F17 -> 0 | H17: =B17-E17 -> 31
A39: TOTAL | E39: =SUM(E4:E37) -> 1676

Sheet 2310
A2: DESCRIPTION | B2: 45953
B3: STOCK INT | C3: RECEPTION | D3: UNITE | E3: SORTIER | F3: PRIX | G3: VALEUR | H3: STOCK
A4: DOUBLE FACE | B4: =+'2210'!H4 -> 59 | D4: ROULEAU | E4: 6 | F4: 230.62 | G4: =E4*F4 -> 1383.72 | H4: =B4-E4 -> 53
A5: SCOTCHE | B5: =+'2210'!H5 -> 75 | D5: ROULEAU | F5: 91.2 | G5: =E5*F5 -> 0 | H5: =B5-E5 -> 75
A6: FEUILLARD N12 | B6: =+'2210'!H6 -> 225 | D6: ROULEAU | E6: 3 | F6: 3500 | G6: =E6*F6 -> 10500 | H6: =B6-E6 -> 222
A7: FEUILLARD N5 | B7: =+'2210'!H7 -> 17 | D7: ROULEAU | E7: 1 | F7: 3300 | G7: =E7*F7 -> 3300 | H7: =B7-E7 -> 16
A8: CELOPHANE 7 | B8: =+'2210'!H8 -> 49 | D8: ROULEAU | F8: 1554.62 | G8: =E8*F8 -> 0 | H8: =B8-E8 -> 49
A9: CELOPHANE 16 | B9: =+'2210'!H9 -> 2476 | D9: KG | E9: =16*3 -> 48 | F9: 210 | G9: =E9*F9 -> 10080 | H9: =B9-E9 -> 2428
A10: CELOPHANE 25 | B10: =+'2210'!H10 -> 24 | D10: KG | G10: =E10*F10 -> 0 | H10: =B10-E10 -> 24
A11: COLLE | B11: =+'2210'!H11 -> 1320 | D11: KG | E11: 90 | F11: 290 | G11: =E11*F11 -> 26100 | H11: =B11-E11 -> 1230
A12: SEL | B12: =+'2210'!H12 -> 2875 | D12: KG | F12: 49.5 | G12: =E12*F12 -> 0 | H12: =B12-E12 -> 2875
A13: BORAX | B13: =+'2210'!H13 -> 475 | D13: KG | E13: 75 | F13: 285 | G13: =E13*F13 -> 21375 | H13: =B13-E13 -> 400
A14: AMIDON | B14: =+'2210'!H14 -> 39700 | D14: KG | E14: 1250 | F14: 93 | G14: =E14*F14 -> 116250 | H14: =B14-E14 -> 38450
A15: SOUDE | B15: =+'2210'!H15 -> 2580 | D15: KG | E15: 56 | F15: 67.23 | G15: =E15*F15 -> 3764.88 | H15: =B15-E15 -> 2524
A16: ANALYFLIX | B16: =+'2210'!H16 -> 350 | D16: L | E16: 25 | F16: 480 | G16: =E16*F16 -> 12000 | H16: =B16-E16 -> 325
A17: FIL RECUIT | B17: =+'2210'!H17 -> 31 | D17: ROULEAU | E17: 5 | G17: =E17*F17 -> 0 | H17: =B17-E17 -> 26
A18: JAUNE MP | C18: 400 | D18: KG | H18: =B18-E18+C18 -> 400
A19: BLUE MP | C19: 200 | D19: KG | H19: =B19-E19+C19 -> 200
A20: MAGENTA MP | C20: 1000 | D20: KG | H20: =B20-E20+C20 -> 1000
A21: NOIR MP | C21: 2600 | D21: KG | H21: =B21-E21+C21 -> 2600
A22: ROUGE MP | C22: 1400 | D22: KG | H22: =B22-E22+C22 -> 1400
A23: BLANC MP | C23: 200 | D23: KG | H23: =B23-E23+C23 -> 200
A24: ORANGE MP | C24: 200 | D24: KG | H24: =B24-E24+C24 -> 200
A25: VERT MP | C25: 1200 | D25: KG | H25: =B25-E25+C25 -> 1200
A26: VIOLET MP | C26: 200 | D26: KG | H26: =B26-E26+C26 -> 200
A27: VERNICH GLOSS | C27: 1000 | D27: KG | H27: =B27-E27+C27 -> 1000
A28: VERNICH CX3 | C28: 14400 | D28: KG | H28: =B28-E28+C28 -> 14400
A29: JAUNE 109 | B29: 120 | D29: KG | H29: =B29-E29+C29 -> 120
A30: JAUNE PROCESS | B30: 100 | D30: KG | H30: =B30-E30+C30 -> 100
A31: BLEU CYAN C | B31: 60 | D31: KG | H31: =B31-E31+C31 -> 60
A32: BLEU REFLEX | B32: 80 | D32: KG | H32: =B32-E32+C32 -> 80
A33: BLEU 295 C | B33: 20 | D33: KG | H33: =B33-E33+C33 -> 20
A34: BLEU BADIRA C | B34: 40 | D34: KG | H34: =B34-E34+C34 -> 40
A35: BLEU 2765 C | B35: 60 | D35: KG | H35: =B35-E35+C35 -> 60
A36: BLEU 3557 | B36: 60 | D36: KG | H36: =B36-E36+C36 -> 60
A37: MARRON 7570 | B37: 100 | D37: KG | H37: =B37-E37+C37 -> 100
A38: MARRON 876 | B38: 20 | D38: KG | H38: =B38-E38+C38 -> 20
A39: MARRON 476 | B39: 20 | D39: KG | H39: =B39-E39+C39 -> 20
A40: MARRON BEJE | B40: 40 | D40: KG | H40: =B40-E40+C40 -> 40
... A61: P200 | B61: 40 | D61: KG | H61: =B61-E61+C61 -> 40
...

Sheet 2510
A2: DESCRIPTION | B2: 45955
B3: STOCK INT | C3: RECEPTION | D3: UNITE | E3: SORTIER | F3: PRIX | G3: VALEUR | H3: STOCK
A4: DOUBLE FACE | B4: =+'2310'!H4 -> 53 | D4: ROULEAU | F4: 230.62 | G4: =E4*F4 -> 0 | H4: =B4-E4 -> 53
A5: SCOTCHE | B5: =+'2310'!H5 -> 75 | D5: ROULEAU | E5: 3 | F5: 91.2 | G5: =E5*F5 -> 273.6 | H5: =B5-E5 -> 72
A6: FEUILLARD N12 | B6: =+'2310'!H6 -> 222 | D6: ROULEAU | F6: 3500 | G6: =E6*F6 -> 0 | H6: =B6-E6 -> 222
A7: FEUILLARD N5 | B7: =+'2310'!H7 -> 16 | D7: ROULEAU | F7: 3300 | G7: =E7*F7 -> 0 | H7: =B7-E7 -> 16
A8: CELOPHANE 7 | B8: =+'2310'!H8 -> 49 | D8: ROULEAU | F8: 1554.62 | G8: =E8*F8 -> 0 | H8: =B8-E8 -> 49
A9: CELOPHANE 16 | B9: =+'2310'!H9 -> 2428 | D9: KG | E9: 32 | F9: 210 | G9: =E9*F9 -> 6720 | H9: =B9-E9 -> 2396
A10: CELOPHANE 25 | B10: =+'2310'!H10 -> 24 | D10: KG | G10: =E10*F10 -> 0 | H10: =B10-E10 -> 24
A11: COLLE | B11: =+'2310'!H11 -> 1230 | D11: KG | F11: 290 | G11: =E11*F11 -> 0 | H11: =B11-E11 -> 1230
A12: SEL | B12: =+'2310'!H12 -> 2875 | D12: KG | F12: 49.5 | G12: =E12*F12 -> 0 | H12: =B12-E12 -> 2875
A13: BORAX | B13: =+'2310'!H13 -> 400 | D13: KG | F13: 285 | G13: =E13*F13 -> 0 | H13: =B13-E13 -> 400
A14: AMIDON | B14: =+'2310'!H14 -> 38450 | C14: 25000 | D14: KG | E14: =21*25 -> 525 | F14: 93 | G14: =E14*F14 -> 48825 | H14: =B14-E14 -> 37925
A15: SOUDE | B15: =+'2310'!H15 -> 2524 | D15: KG | E15: 42 | F15: 67.23 | G15: =E15*F15 -> 2823.66 | H15: =B15-E15 -> 2482
A16: ANALYFLIX | B16: =+'2310'!H16 -> 325 | D16: L | F16: 480 | G16: =E16*F16 -> 0 | H16: =B16-E16 -> 325
A17: FIL RECUIT | B17: =+'2310'!H17 -> 26 | D17: ROULEAU | G17: =E17*F17 -> 0 | H17: =B17-E17 -> 26
A18: JAUNE MP | B18: 1640.1 | C18: 400 | D18: KG | E18: 91.7 | F18: 877.28 | G18: =E18*F18 -> 80446.576 | H18: =B18-E18 -> 1548.4
A19: BLUE MP | B19: 373 | C19: 200 | D19: KG | E19: 12.45 | F19: 601.1 | G19: =E19*F19 -> 7483.695 | H19: =B19-E19 -> 360.55
A20: MAGENTA MP | B20: =+'2310'!H20 -> 1000 | C20: 1000 | D20: KG | E20: 9.5 | F20: 568.61 | G20: =E20*F20 -> 5401.795 | H20: =B20-E20 -> 990.5
A21: NOIR MP | B21: =+'2310'!H21 -> 2600 | C21: 2600 | D21: KG | E21: 135.4 | F21: 333.04 | G21: =E21*F21 -> 45093.616 | H21: =B21-E21 -> 2464.6
A22: ROUGE MP | B22: =+'2310'!H22 -> 1400 | C22: 1400 | D22: KG | E22: 122.75 | F22: 714.82 | G22: =E22*F22 -> 87744.155 | H22: =B22-E22 -> 1277.25
A23: BLANC MP | B23: 230 | C23: 200 | D23: KG | F23: 487.38 | G23: =E23*F23 -> 0 | H23: =B23-E23 -> 230
A24: ORANGE MP | B24: 980.9 | C24: 200 | D24: KG | E24: 4.63 | F24: 844.79 | G24: =E24*F24 -> 3911.3777 | H24: =B24-E24 -> 976.27
A25: VERT MP | B25: =+'2310'!H25 -> 1200 | C25: 1200 | D25: KG | E25: 96 | F25: 901.65 | G25: =E25*F25 -> 86558.4 | H25: =B25-E25 -> 1104
A26: VIOLET MP | B26: 269.88 | C26: 200 | D26: KG | E26: 29 | F26: 877.28 | G26: =E26*F26 -> 25441.12 | H26: =B26-E26 -> 240.88
A27: VERNICH GLOSS | B27: 1130 | C27: 1000 | D27: KG | E27: 59.3 | F27: 300.55 | G27: =E27*F27 -> 17822.615 | H27: =B27-E27 -> 1070.7
A28: VERNICH CX3 | B28: 15493.88 | C28: 14400 | D28: KG | E28: 656.7 | F28: 178.7 | G28: =E28*F28 -> 117352.29 | H28: =B28-E28 -> 14837.18
A29: JAUNE 109 | B29: 410 | D29: KG | E29: 391 | G29: =E29*F29 -> 0 | H29: =B29-E29 -> 19
A30: JAUNE PROCESS | B30: =+'2310'!H30 -> 100 | D30: KG | E30: 100 | G30: =E30*F30 -> 0 | H30: =B30-E30 -> 0
A31: BLEU CYAN | B31: 100 | D31: KG | H31: =B31-E31 -> 100
A32: BLEU CYAN C | B32: =+'2310'!H31 -> 60 | D32: KG | G32: =E32*F32 -> 0 | H32: =B32-E32 -> 60
A33: BLEU REFLEX | B33: 300 | D33: KG | E33: 151 | G33: =E33*F33 -> 0 | H33: =B33-E33 -> 149
A34: BLEU 295 C | B34: =+'2310'!H33 -> 20 | D34: KG | G34: =E34*F34 -> 0 | H34: =B34-E34 -> 20
A35: BLEU BADIRA C | B35: =+'2310'!H34 -> 40 | D35: KG | G35: =E35*F35 -> 0 | H35: =B35-E35 -> 40
A36: BLEU 2765 C | B36: =+'2310'!H35 -> 60 | D36: KG | G36: =E36*F36 -> 0 | H36: =B36-E36 -> 60
A37: BLEU 3557 | B37: =+'2310'!H36 -> 60 | D37: KG | G37: =E37*F37 -> 0 | H37: =B37-E37 -> 60
A38: MARRON 7570 | B38: =+'2310'!H37 -> 100 | D38: KG | G38: =E38*F38 -> 0 | H38: =B38-E38 -> 100
A39: MARRON 876 | B39: =+'2310'!H38 -> 20 | D39: KG | G39: =E39*F39 -> 0 | H39: =B39-E39 -> 20
A40: MARRON 476 | B40: =+'2310'!H39 -> 20 | D40: KG | G40: =E40*F40 -> 0 | H40: =B40-E40 -> 20
A41: MARRON BEJE | B41: =+'2310'!H40 -> 40 | D41: KG | G41: =E41*F41 -> 0 | H41: =B41-E41 -> 40
...

Sheet 2710
A2: DESCRIPTION | B2: 45957
B3: STOCK INT | C3: RECEPTION | D3: UNITE | E3: SORTIER | F3: PRIX | G3: VALEUR | H3: STOCK
A4: DOUBLE FACE | B4: =+'2510'!H4 -> 53 | D4: ROULEAU | E4: 6 | F4: 230.62 | G4: =E4*F4 -> 1383.72 | H4: =B4-E4 -> 47
A5: SCOTCHE | B5: =+'2510'!H5 -> 72 | D5: ROULEAU | E5: 3 | F5: 91.2 | G5: =E5*F5 -> 273.6 | H5: =B5-E5 -> 69
A6: FEUILLARD N12 | B6: =+'2510'!H6 -> 222 | D6: ROULEAU | F6: 3500 | G6: =E6*F6 -> 0 | H6: =B6-E6 -> 222
A7: FEUILLARD N5 | B7: =+'2510'!H7 -> 16 | D7: ROULEAU | F7: 3300 | G7: =E7*F7 -> 0 | H7: =B7-E7 -> 16
A8: CELOPHANE 7 | B8: =+'2510'!H8 -> 49 | D8: ROULEAU | F8: 1554.62 | G8: =E8*F8 -> 0 | H8: =B8-E8 -> 49
A9: CELOPHANE 16 | B9: =+'2510'!H9 -> 2396 | D9: KG | F9: 210 | G9: =E9*F9 -> 0 | H9: =B9-E9 -> 2396
A10: CELOPHANE 25 | B10: =+'2510'!H10 -> 24 | D10: KG | G10: =E10*F10 -> 0 | H10: =B10-E10 -> 24
A11: COLLE | B11: =+'2510'!H11 -> 1230 | D11: KG | F11: 290 | G11: =E11*F11 -> 0 | H11: =B11-E11 -> 1230
A12: SEL | B12: =+'2510'!H12 -> 2875 | D12: KG | E12: =2*25 -> 50 | F12: 49.5 | G12: =E12*F12 -> 2475 | H12: =B12-E12 -> 2825
A13: BORAX | B13: =+'2510'!H13 -> 400 | D13: KG | F13: 285 | G13: =E13*F13 -> 0 | H13: =B13-E13 -> 400
A14: AMIDON | B14: =+'2510'!H14 -> 37925 | C14: 25000 | D14: KG | E14: =56*25 -> 1400 | F14: 93 | G14: =E14*F14 -> 130200 | H14: =B14-E14+C14 -> 61525
A15: SOUDE | B15: =+'2510'!H15 -> 2482 | D15: KG | E15: 84 | F15: 67.23 | G15: =E15*F15 -> 5647.32 | H15: =B15-E15 -> 2398
A16: ANALYFLIX | B16: =+'2510'!H16 -> 325 | D16: L | F16: 480 | G16: =E16*F16 -> 0 | H16: =B16-E16 -> 325
A17: FIL RECUIT | B17: =+'2510'!H17 -> 26 | D17: ROULEAU | G17: =E17*F17 -> 0 | H17: =B17-E17 -> 26
A18: JAUNE MP | B18: =+'2510'!H18 -> 1548.4 | D18: KG | E18: 1.177 | F18: 877.28 | G18: =E18*F18 -> 1032.5586 | H18: =B18-E18 -> 1547.223
A19: BLUE MP | B19: =+'2510'!H19 -> 360.55 | D19: KG | E19: 4.44 | F19: 601.1 | G19: =E19*F19 -> 2668.884 | H19: =B19-E19 -> 356.11
A20: MAGENTA MP | B20: =+'2510'!H20 -> 990.5 | D20: KG | F20: 568.61 | G20: =E20*F20 -> 0 | H20: =B20-E20 -> 990.5
A21: NOIR MP | B21: =+'2510'!H21 -> 2464.6 | D21: KG | F21: 333.04 | G21: =E21*F21 -> 0 | H21: =B21-E21 -> 2464.6
A22: ROUGE MP | B22: =+'2510'!H22 -> 1277.25 | D22: KG | F22: 714.82 | G22: =E22*F22 -> 0 | H22: =B22-E22 -> 1277.25
A23: BLANC MP | B23: =+'2510'!H23 -> 230 | D23: KG | F23: 487.38 | G23: =E23*F23 -> 0 | H23: =B23-E23 -> 230
A24: ORANGE MP | B24: =+'2510'!H24 -> 976.27 | D24: KG | E24: 1.228 | F24: 844.79 | G24: =E24*F24 -> 1037.4021 | H24: =B24-E24 -> 975.042
A25: VERT MP | B25: =+'2510'!H25 -> 1104 | D25: KG | F25: 901.65 | G25: =E25*F25 -> 0 | H25: =B25-E25 -> 1104
A26: VIOLET MP | B26: =+'2510'!H26 -> 240.88 | D26: KG | F26: 877.28 | G26: =E26*F26 -> 0 | H26: =B26-E26 -> 240.88
A27: VERNICH GLOSS | B27: =+'2510'!H27 -> 1070.7 | D27: KG | E27: 9.69 | F27: 300.55 | G27: =E27*F27 -> 2912.3295 | H27: =B27-E27 -> 1061.01
A28: VERNICH CX3 | B28: =+'2510'!H28 -> 14837.18 | D28: KG | F28: 178.7 | G28: =E28*F28 -> 0 | H28: =B28-E28 -> 14837.18
A29: JAUNE 109 | B29: =+'2510'!H29 -> 19 | D29: KG | G29: =E29*F29 -> 0 | H29: =B29-E29 -> 19
A30: JAUNE PROCESS | B30: =+'2510'!H30 -> 0 | D30: KG | G30: =E30*F30 -> 0 | H30: =B30-E30 -> 0
A31: BLEU CYAN | B31: =+'2510'!H31 -> 100 | D31: KG | G31: =E31*F31 -> 0 | H31: =B31-E31 -> 100
A32: BLEU CYAN C | B32: =+'2510'!H32 -> 60 | D32: KG | G32: =E32*F32 -> 0 | H32: =B32-E32 -> 60
A33: BLEU REFLEX | B33: =+'2510'!H33 -> 149 | D33: KG | G33: =E33*F33 -> 0 | H33: =B33-E33 -> 149
A34: BLEU 295 C | B34: =+'2510'!H34 -> 20 | D34: KG | G34: =E34*F34 -> 0 | H34: =B34-E34 -> 20
A35: BLEU BADIRA C | B35: =+'2510'!H35 -> 40 | D35: KG | G35: =E35*F35 -> 0 | H35: =B35-E35 -> 40
A36: BLEU 2765 C | B36: =+'2510'!H36 -> 60 | D36: KG | G36: =E36*F36 -> 0 | H36: =B36-E36 -> 60
A37: BLEU 3557 | B37: =+'2510'!H37 -> 60 | D37: KG | G37: =E37*F37 -> 0 | H37: =B37-E37 -> 60
A38: MARRON 7570 | B38: =+'2510'!H38 -> 100 | D38: KG | G38: =E38*F38 -> 0 | H38: =B38-E38 -> 100
A39: MARRON 876 | B39: =+'2510'!H39 -> 20 | D39: KG | G39: =E39*F39 -> 0 | H39: =B39-E39 -> 20
A40: MARRON 476 | B40: =+'2510'!H40 -> 20 | D40: KG | G40: =E40*F40 -> 0 | H40: =B40-E40 -> 20
... A46: ROUGE 3546 | B46: =+'2510'!H46 -> 83 | D46: KG | G46: =E46*F46 -> 0 | H46: =B46-E46 -> 83
...

Sheet 2810
A2: DESCRIPTION | B2: 45958
B3: STOCK INT | C3: RECEPTION | D3: UNITE | E3: SORTIER | F3: PRIX | G3: VALEUR | H3: STOCK
A4: DOUBLE FACE | B4: =+'2710'!H4 -> 47 | D4: ROULEAU | E4: 6 | F4: 230.62 | G4: =E4*F4 -> 1383.72 | H4: =B4-E4 -> 41
A5: SCOTCHE | B5: =+'2710'!H5 -> 69 | D5: ROULEAU | F5: 91.2 | G5: =E5*F5 -> 0 | H5: =B5-E5 -> 69
A6: FEUILLARD N12 | B6: =+'2710'!H6 -> 222 | D6: ROULEAU | E6: 1 | F6: 3500 | G6: =E6*F6 -> 3500 | H6: =B6-E6 -> 221
A7: FEUILLARD N5 | B7: =+'2710'!H7 -> 16 | D7: ROULEAU | E7: 1 | F7: 3300 | G7: =E7*F7 -> 3300 | H7: =B7-E7 -> 15
A8: CELOPHANE 7 | B8: =+'2710'!H8 -> 49 | D8: ROULEAU | F8: 1554.62 | G8: =E8*F8 -> 0 | H8: =B8-E8 -> 49
A9: CELOPHANE 16 | B9: =+'2710'!H9 -> 2396 | D9: KG | F9: 210 | G9: =E9*F9 -> 0 | H9: =B9-E9 -> 2396
A10: CELOPHANE 25 | B10: =+'2710'!H10 -> 24 | D10: KG | G10: =E10*F10 -> 0 | H10: =B10-E10 -> 24
A11: COLLE | B11: =+'2710'!H11 -> 1230 | D11: KG | E11: 60 | F11: 290 | G11: =E11*F11 -> 17400 | H11: =B11-E11 -> 1170
A12: SEL | B12: =+'2710'!H12 -> 2825 | D12: KG | F12: 49.5 | G12: =E12*F12 -> 0 | H12: =B12-E12 -> 2825
A13: BORAX | B13: =+'2710'!H13 -> 400 | D13: KG | F13: 285 | G13: =E13*F13 -> 0 | H13: =B13-E13 -> 400
A14: AMIDON | B14: =+'2710'!H14 -> 61525 | D14: KG | E14: =70*25 -> 1750 | F14: 93 | G14: =E14*F14 -> 162750 | H14: =B14-E14 -> 59775
A15: SOUDE | B15: =+'2710'!H15 -> 2398 | D15: KG | E15: 56 | F15: 67.23 | G15: =E15*F15 -> 3764.88 | H15: =B15-E15 -> 2342
A16: ANALYFLIX | B16: =+'2710'!H16 -> 325 | D16: L | F16: 480 | G16: =E16*F16 -> 0 | H16: =B16-E16 -> 325
A17: FIL RECUIT | B17: =+'2710'!H17 -> 26 | D17: ROULEAU | G17: =E17*F17 -> 0 | H17: =B17-E17 -> 26
A18: JAUNE MP | B18: =+'2710'!H18 -> 1547.223 | D18: KG | F18: 877.28 | G18: =E18*F18 -> 0 | H18: =B18-E18 -> 1547.223
A19: BLUE MP | B19: =+'2710'!H19 -> 356.11 | D19: KG | F19: 601.1 | G19: =E19*F19 -> 0 | H19: =B19-E19 -> 356.11
A20: MAGENTA MP | B20: =+'2710'!H20 -> 990.5 | D20: KG | F20: 568.61 | G20: =E20*F20 -> 0 | H20: =B20-E20 -> 990.5
A21: NOIR MP | B21: =+'2710'!H21 -> 2464.6 | D21: KG | F21: 333.04 | G21: =E21*F21 -> 0 | H21: =B21-E21 -> 2464.6
A22: ROUGE MP | B22: =+'2710'!H22 -> 1277.25 | D22: KG | F22: 714.82 | G22: =E22*F22 -> 0 | H22: =B22-E22 -> 1277.25
A23: BLANC MP | B23: =+'2710'!H23 -> 230 | D23: KG | F23: 487.38 | G23: =E23*F23 -> 0 | H23: =B23-E23 -> 230
A24: ORANGE MP | B24: =+'2710'!H24 -> 975.042 | D24: KG | F24: 844.79 | G24: =E24*F24 -> 0 | H24: =B24-E24 -> 975.042
A25: VERT MP | B25: =+'2710'!H25 -> 1104 | D25: KG | F25: 901.65 | G25: =E25*F25 -> 0 | H25: =B25-E25 -> 1104
A26: VIOLET MP | B26: =+'2710'!H26 -> 240.88 | D26: KG | F26: 877.28 | G26: =E26*F26 -> 0 | H26: =B26-E26 -> 240.88
A27: VERNICH GLOSS | B27: =+'2710'!H27 -> 1061.01 | D27: KG | F27: 300.55 | G27: =E27*F27 -> 0 | H27: =B27-E27 -> 1061.01
A28: VERNICH CX3 | B28: =+'2710'!H28 -> 14837.18 | D28: KG | F28: 178.7 | G28: =E28*F28 -> 0 | H28: =B28-E28 -> 14837.18
A29: JAUNE 109 | B29: =+'2710'!H29 -> 19 | D29: KG | G29: =E29*F29 -> 0 | H29: =B29-E29 -> 19
A30: JAUNE PROCESS | B30: =+'2710'!H30 -> 0 | D30: KG | G30: =E30*F30 -> 0 | H30: =B30-E30 -> 0
A31: BLEU CYAN | B31: =+'2710'!H31 -> 100 | D31: KG | G31: =E31*F31 -> 0 | H31: =B31-E31 -> 100
A32: BLEU CYAN C | B32: =+'2710'!H32 -> 60 | D32: KG | G32: =E32*F32 -> 0 | H32: =B32-E32 -> 60
A33: BLEU REFLEX | B33: =+'2710'!H33 -> 149 | D33: KG | G33: =E33*F33 -> 0 | H33: =B33-E33 -> 149
A34: BLEU 295 C | B34: =+'2710'!H34 -> 20 | D34: KG | G34: =E34*F34 -> 0 | H34: =B34-E34 -> 20
A35: BLEU BADIRA C | B35: =+'2710'!H35 -> 40 | D35: KG | G35: =E35*F35 -> 0 | H35: =B35-E35 -> 40
A36: BLEU 2765 C | B36: =+'2710'!H36 -> 60 | D36: KG | G36: =E36*F36 -> 0 | H36: =B36-E36 -> 60
A37: BLEU 3557 | B37: =+'2710'!H37 -> 60 | D37: KG | G37: =E37*F37 -> 0 | H37: =B37-E37 -> 60
A38: MARRON 7570 | B38: =+'2710'!H38 -> 100 | D38: KG | G38: =E38*F38 -> 0 | H38: =B38-E38 -> 100
A39: MARRON 876 | B39: =+'2710'!H39 -> 20 | D39: KG | G39: =E39*F39 -> 0 | H39: =B39-E39 -> 20
A40: MARRON 476 | B40: =+'2710'!H40 -> 20 | D40: KG | G40: =E40*F40 -> 0 | H40: =B40-E40 -> 20
... A42: MARRON 7502 | B42: =+'2710'!H42 -> 100 | D42: KG | G42: =E42*F42 -> 0 | H42: =B42-E42 -> 100
...

Sheet 2910
A2: DESCRIPTION | B2: 45959
B3: STOCK INT | C3: RECEPTION | D3: UNITE | E3: SORTIER | F3: PRIX | G3: VALEUR | H3: STOCK
A4: DOUBLE FACE | B4: =+'2810'!H4 -> 41 | D4: ROULEAU | E4: 3 | F4: 230.62 | G4: =E4*F4 -> 691.86 | H4: =B4-E4 -> 38
A5: SCOTCHE | B5: =+'2810'!H5 -> 69 | D5: ROULEAU | E5: 3 | F5: 91.2 | G5: =E5*F5 -> 273.6 | H5: =B5-E5 -> 66
A6: FEUILLARD N12 | B6: =+'2810'!H6 -> 221 | D6: ROULEAU | E6: 2 | F6: 3500 | G6: =E6*F6 -> 7000 | H6: =B6-E6 -> 219
A7: FEUILLARD N5 | B7: =+'2810'!H7 -> 15 | D7: ROULEAU | E7: 1 | F7: 3300 | G7: =E7*F7 -> 3300 | H7: =B7-E7 -> 14
A8: CELOPHANE 7 | B8: =+'2810'!H8 -> 49 | D8: ROULEAU | E8: 1 | F8: 1554.62 | G8: =E8*F8 -> 1554.62 | H8: =B8-E8 -> 48
A9: CELOPHANE 16 | B9: =+'2810'!H9 -> 2396 | D9: KG | E9: 48 | F9: 210 | G9: =E9*F9 -> 10080 | H9: =B9-E9 -> 2348
A10: CELOPHANE 25 | B10: =+'2810'!H10 -> 24 | D10: KG | G10: =E10*F10 -> 0 | H10: =B10-E10 -> 24
A11: COLLE | B11: =+'2810'!H11 -> 1170 | D11: KG | F11: 290 | G11: =E11*F11 -> 0 | H11: =B11-E11 -> 1170
A12: SEL | B12: =+'2810'!H12 -> 2825 | D12: KG | E12: 100 | F12: 49.5 | G12: =E12*F12 -> 4950 | H12: =B12-E12 -> 2725
A13: BORAX | B13: =+'2810'!H13 -> 400 | D13: KG | F13: 285 | G13: =E13*F13 -> 0 | H13: =B13-E13 -> 400
A14: AMIDON | B14: =+'2810'!H14 -> 59775 | D14: KG | E14: =20*25 -> 500 | F14: 93 | G14: =E14*F14 -> 46500 | H14: =B14-E14 -> 59275
A15: SOUDE | B15: =+'2810'!H15 -> 2342 | D15: KG | E15: 56 | F15: 67.23 | G15: =E15*F15 -> 3764.88 | H15: =B15-E15 -> 2286
A16: ANALYFLIX | B16: =+'2810'!H16 -> 325 | D16: KG | F16: 480 | G16: =E16*F16 -> 0 | H16: =B16-E16 -> 325
A17: FIL RECUIT | B17: =+'2810'!H17 -> 26 | D17: ROULEAU | G17: =E17*F17 -> 0 | H17: =B17-E17 -> 26
A18: JAUNE MP | B18: =+'2810'!H18 -> 1547.223 | D18: KG | F18: 877.28 | G18: =E18*F18 -> 0 | H18: =B18-E18 -> 1547.223
A19: BLUE MP | B19: =+'2810'!H19 -> 356.11 | D19: KG | E19: =4.029 -> 4.029 | F19: 601.1 | G19: =E19*F19 -> 2421.8319 | H19: =B19-E19 -> 352.081
A20: MAGENTA MP | B20: =+'2810'!H20 -> 990.5 | D20: KG | F20: 568.61 | G20: =E20*F20 -> 0 | H20: =B20-E20 -> 990.5
A21: NOIR MP | B21: =+'2810'!H21 -> 2464.6 | D21: KG | E21: =1.831 -> 1.831 | F21: 333.04 | G21: =E21*F21 -> 609.79624 | H21: =B21-E21 -> 2462.769
A22: ROUGE MP | B22: =+'2810'!H22 -> 1277.25 | D22: KG | F22: 714.82 | G22: =E22*F22 -> 0 | H22: =B22-E22 -> 1277.25
A23: BLANC MP | B23: =+'2810'!H23 -> 230 | D23: KG | F23: 487.38 | G23: =E23*F23 -> 0 | H23: =B23-E23 -> 230
A24: ORANGE MP | B24: =+'2810'!H24 -> 975.042 | D24: KG | F24: 844.79 | G24: =E24*F24 -> 0 | H24: =B24-E24 -> 975.042
A25: VERT MP | B25: =+'2810'!H25 -> 1104 | D25: KG | F25: 901.65 | G25: =E25*F25 -> 0 | H25: =B25-E25 -> 1104
A26: VIOLET MP | B26: =+'2810'!H26 -> 240.88 | D26: KG | E26: =5.86 -> 5.86 | F26: 877.28 | G26: =E26*F26 -> 5140.8608 | H26: =B26-E26 -> 235.02
A27: VERNICH GLOSS | B27: =+'2810'!H27 -> 1061.01 | D27: KG | F27: 300.55 | G27: =E27*F27 -> 0 | H27: =B27-E27 -> 1061.01
A28: VERNICH CX3 | B28: =+'2810'!H28 -> 14837.18 | D28: KG | E28: =4.759 -> 4.759 | F28: 178.7 | G28: =E28*F28 -> 850.4333 | H28: =B28-E28 -> 14832.421
A29: JAUNE 109 | B29: =+'2810'!H29 -> 19 | D29: KG | G29: =E29*F29 -> 0 | H29: =B29-E29 -> 19
A30: JAUNE PROCESS | B30: =+'2810'!H30 -> 0 | D30: KG | G30: =E30*F30 -> 0 | H30: =B30-E30 -> 0
A31: BLEU CYAN | B31: =+'2810'!H31 -> 100 | D31: KG | G31: =E31*F31 -> 0 | H31: =B31-E31 -> 100
A32: BLEU CYAN C | B32: =+'2810'!H32 -> 60 | D32: KG | G32: =E32*F32 -> 0 | H32: =B32-E32 -> 60
A33: BLEU REFLEX | B33: =+'2810'!H33 -> 149 | D33: KG | G33: =E33*F33 -> 0 | H33: =B33-E33 -> 149
A34: BLEU 295 C | B34: =+'2810'!H34 -> 20 | D34: KG | E34: 20 | G34: =E34*F34 -> 0 | H34: =B34-E34 -> 0
A35: BLEU BADIRA C | B35: =+'2810'!H35 -> 40 | D35: KG | G35: =E35*F35 -> 0 | H35: =B35-E35 -> 40
A36: BLEU BADIRA | B36: 17 | D36: KG | G36: =E36*F36 -> 0 | H36: =B36-E36 -> 17
A37: BLEU 2765 C | B37: =+'2810'!H36 -> 60 | D37: KG | E37: 20 | G37: =E37*F37 -> 0 | H37: =B37-E37 -> 40
A38: BLEU 3557 | B38: =+'2810'!H37 -> 60 | D38: KG | G38: =E38*F38 -> 0 | H38: =B38-E38 -> 60
A39: MARRON 7570 | B39: =+'2810'!H38 -> 100 | D39: KG | G39: =E39*F39 -> 0 | H39: =B39-E39 -> 100
A40: MARRON 876 | B40: =+'2810'!H39 -> 20 | D40: KG | G40: =E40*F40 -> 0 | H40: =B40-E40 -> 20
A41: MARRON 476 | B41: =+'2810'!H40 -> 20 | D41: KG | G41: =E41*F41 -> 0 | H41: =B41-E41 -> 20
...

Sheet 3010
A2: DESCRIPTION | B2: 45960
B3: STOCK INT | C3: RECEPTION | D3: UNITE | E3: SORTIER | F3: PRIX | G3: VALEUR | H3: STOCK
A4: DOUBLE FACE | B4: =+'2910'!H4 -> 38 | D4: ROULEAU | E4: 6 | F4: 230.62 | G4: =E4*F4 -> 1383.72 | H4: =B4-E4 -> 32
A5: SCOTCHE | B5: =+'2910'!H5 -> 66 | D5: ROULEAU | E5: 5 | F5: 91.2 | G5: =E5*F5 -> 456 | H5: =B5-E5 -> 61
A6: FEUILLARD N12 | B6: =+'2910'!H6 -> 219 | D6: ROULEAU | E6: 3 | F6: 3500 | G6: =E6*F6 -> 10500 | H6: =B6-E6 -> 216
A7: FEUILLARD N5 | B7: =+'2910'!H7 -> 14 | D7: ROULEAU | E7: 3 | F7: 3300 | G7: =E7*F7 -> 9900 | H7: =B7-E7 -> 11
A8: CELOPHANE 7 | B8: =+'2910'!H8 -> 48 | D8: ROULEAU | F8: 1554.62 | G8: =E8*F8 -> 0 | H8: =B8-E8 -> 48
A9: CELOPHANE 16 | B9: =+'2910'!H9 -> 2348 | D9: KG | F9: 210 | G9: =E9*F9 -> 0 | H9: =B9-E9 -> 2348
A10: CELOPHANE 25 | B10: =+'2910'!H10 -> 24 | D10: KG | G10: =E10*F10 -> 0 | H10: =B10-E10 -> 24
A11: COLLE | B11: =+'2910'!H11 -> 1170 | D11: KG | E11: 60 | F11: 290 | G11: =E11*F11 -> 17400 | H11: =B11-E11 -> 1110
A12: SEL | B12: =+'2910'!H12 -> 2725 | D12: KG | F12: 49.5 | G12: =E12*F12 -> 0 | H12: =B12-E12 -> 2725
A13: BORAX | B13: =+'2910'!H13 -> 400 | D13: KG | F13: 285 | G13: =E13*F13 -> 0 | H13: =B13-E13 -> 400
A14: AMIDON | B14: =+'2910'!H14 -> 59275 | D14: KG | E14: =30*25 -> 750 | F14: 93 | G14: =E14*F14 -> 69750 | H14: =B14-E14 -> 58525
A15: SOUDE | B15: =+'2910'!H15 -> 2286 | D15: KG | E15: 56 | F15: 67.23 | G15: =E15*F15 -> 3764.88 | H15: =B15-E15 -> 2230
A16: ANALYFLIX | B16: =+'2910'!H16 -> 325 | D16: KG | F16: 480 | G16: =E16*F16 -> 0 | H16: =B16-E16 -> 325
A17: FIL RECUIT | B17: =+'2910'!H17 -> 26 | D17: ROULEAU | G17: =E17*F17 -> 0 | H17: =B17-E17 -> 26
A18: JAUNE MP | B18: =+'2910'!H18 -> 1547.223 | D18: KG | E18: 12.53 | F18: 877.28 | G18: =E18*F18 -> 10992.318 | H18: =B18-E18 -> 1534.693
A19: BLUE MP | B19: =+'2910'!H19 -> 352.081 | D19: KG | E19: 7.11 | F19: 601.1 | G19: =E19*F19 -> 4273.821 | H19: =B19-E19 -> 344.971
A20: MAGENTA MP | B20: =+'2910'!H20 -> 990.5 | D20: KG | E20: 0.28 | F20: 568.61 | G20: =E20*F20 -> 159.2108 | H20: =B20-E20 -> 990.22
A21: NOIR MP | B21: =+'2910'!H21 -> 2462.769 | D21: KG | E21: 0.4 | F21: 333.04 | G21: =E21*F21 -> 133.216 | H21: =B21-E21 -> 2462.369
A22: ROUGE MP | B22: =+'2910'!H22 -> 1277.25 | D22: KG | E22: 14.72 | F22: 714.82 | G22: =E22*F22 -> 10522.15 | H22: =B22-E22 -> 1262.53
A23: BLANC MP | B23: =+'2910'!H23 -> 230 | D23: KG | F23: 487.38 | G23: =E23*F23 -> 0 | H23: =B23-E23 -> 230
A24: ORANGE MP | B24: =+'2910'!H24 -> 975.042 | D24: KG | E24: 0.39 | F24: 844.79 | G24: =E24*F24 -> 329.4681 | H24: =B24-E24 -> 974.652
A25: VERT MP | B25: =+'2910'!H25 -> 1104 | D25: KG | F25: 901.65 | G25: =E25*F25 -> 0 | H25: =B25-E25 -> 1104
A26: VIOLET MP | B26: =+'2910'!H26 -> 235.02 | D26: KG | E26: 5.98 | F26: 877.28 | G26: =E26*F26 -> 5246.1344 | H26: =B26-E26 -> 229.04
A27: VERNICH GLOSS | B27: =+'2910'!H27 -> 1061.01 | D27: KG | E27: 91.2 | F27: 300.55 | G27: =E27*F27 -> 27410.16 | H27: =B27-E27 -> 969.81
A28: VERNICH CX3 | B28: =+'2910'!H28 -> 14832.421 | D28: KG | E28: 16.55 | F28: 178.7 | G28: =E28*F28 -> 2957.485 | H28: =B28-E28 -> 14815.871
A29: JAUNE 109 | B29: =+'2910'!H29 -> 19 | D29: KG | G29: =E29*F29 -> 0 | H29: =B29-E29 -> 19
A30: JAUNE 4018 | B30: 20 | D30: KG | E30: 20 | G30: =E30*F30 -> 0 | H30: =B30-E30 -> 0
A31: JAUNE PROCESS | B31: =+'2910'!H30 -> 0 | D31: KG | G31: =E31*F31 -> 0 | H31: =B31-E31 -> 0
A32: JAUNE PROCESS C | B32: 40 | D32: KG | G32: =E32*F32 -> 0 | H32: =B32-E32 -> 40
A33: BLEU CYAN | B33: =+'2910'!H31 -> 100 | D33: KG | G33: =E33*F33 -> 0 | H33: =B33-E33 -> 100
A34: BLEU CYAN C | B34: =+'2910'!H32 -> 60 | D34: KG | G34: =E34*F34 -> 0 | H34: =B34-E34 -> 60
A35: BLEU REFLEX | B35: =+'2910'!H33 -> 149 | D35: KG | E35: 17 | G35: =E35*F35 -> 0 | H35: =B35-E35 -> 132
A36: BLEU REFLEX COUCHE | B36: 60 | D36: KG | G36: =E36*F36 -> 0 | H36: =B36-E36 -> 60
A37: BLEU 295 C | B37: =+'2910'!H34 -> 0 | D37: KG | G37: =E37*F37 -> 0 | H37: =B37-E37 -> 0
A38: BLEU BADIRA C | B38: =+'2910'!H35 -> 40 | D38: KG | G38: =E38*F38 -> 0 | H38: =B38-E38 -> 40
A39: BLEU BADIRA | B39: =+'2910'!H36 -> 17 | D39: KG | G39: =E39*F39 -> 0 | H39: =B39-E39 -> 17
A40: BLEU 2765 C | B40: =+'2910'!H37 -> 40 | D40: KG | G40: =E40*F40 -> 0 | H40: =B40-E40 -> 40
A41: BLEU 3557 | B41: =+'2910'!H38 -> 60 | D41: KG | G41: =E41*F41 -> 0 | H41: =B41-E41 -> 60
...

Sheet 0111
A2: DESCRIPTION | B2: 45962
B3: STOCK INT | C3: RECEPTION | D3: UNITE | E3: SORTIER | F3: PRIX | G3: VALEUR | H3: STOCK
A4: DOUBLE FACE | B4: =+'3010'!H4 -> 32 | D4: ROULEAU | F4: 230.62 | G4: =E4*F4 -> 0 | H4: =B4-E4 -> 32
A5: SCOTCHE | B5: =+'3010'!H5 -> 61 | D5: ROULEAU | F5: 91.2 | G5: =E5*F5 -> 0 | H5: =B5-E5 -> 61
A6: FEUILLARD N12 | B6: =+'3010'!H6 -> 216 | D6: ROULEAU | F6: 3500 | G6: =E6*F6 -> 0 | H6: =B6-E6 -> 216
A7: FEUILLARD N5 | B7: =+'3010'!H7 -> 11 | D7: ROULEAU | F7: 3300 | G7: =E7*F7 -> 0 | H7: =B7-E7 -> 11
A8: CELOPHANE 7 | B8: =+'3010'!H8 -> 48 | D8: ROULEAU | F8: 1554.62 | G8: =E8*F8 -> 0 | H8: =B8-E8 -> 48
A9: CELOPHANE 16 | B9: =+'3010'!H9 -> 2348 | D9: KG | E9: 32 | F9: 210 | G9: =E9*F9 -> 6720 | H9: =B9-E9 -> 2316
A10: CELOPHANE 25 | B10: =+'3010'!H10 -> 24 | D10: KG | G10: =E10*F10 -> 0 | H10: =B10-E10 -> 24
A11: COLLE | B11: =+'3010'!H11 -> 1110 | D11: KG | F11: 290 | G11: =E11*F11 -> 0 | H11: =B11-E11 -> 1110
A12: SEL | B12: =+'3010'!H12 -> 2725 | D12: KG | F12: 49.5 | G12: =E12*F12 -> 0 | H12: =B12-E12 -> 2725
A13: BORAX | B13: =+'3010'!H13 -> 400 | D13: KG | F13: 285 | G13: =E13*F13 -> 0 | H13: =B13-E13 -> 400
A14: AMIDON | B14: =+'3010'!H14 -> 58525 | D14: KG | E14: =70*25 -> 1750 | F14: 93 | G14: =E14*F14 -> 162750 | H14: =B14-E14 -> 56775
A15: SOUDE | B15: =+'3010'!H15 -> 2230 | D15: KG | E15: 98 | F15: 67.23 | G15: =E15*F15 -> 6588.54 | H15: =B15-E15 -> 2132
A16: ANALYFLIX | B16: =+'3010'!H16 -> 325 | D16: KG | F16: 480 | G16: =E16*F16 -> 0 | H16: =B16-E16 -> 325
A17: FIL RECUIT | B17: =+'3010'!H17 -> 26 | D17: ROULEAU | G17: =E17*F17 -> 0 | H17: =B17-E17 -> 26
A18: JAUNE MP | B18: =+'3010'!H18 -> 1534.693 | D18: KG | F18: 877.28 | G18: =E18*F18 -> 0 | H18: =B18-E18 -> 1534.693
A19: BLUE MP | B19: =+'3010'!H19 -> 344.971 | D19: KG | F19: 601.1 | G19: =E19*F19 -> 0 | H19: =B19-E19 -> 344.971
A20: MAGENTA MP | B20: =+'3010'!H20 -> 990.22 | D20: KG | F20: 568.61 | G20: =E20*F20 -> 0 | H20: =B20-E20 -> 990.22
A21: NOIR MP | B21: =+'3010'!H21 -> 2462.369 | D21: KG | F21: 333.04 | G21: =E21*F21 -> 0 | H21: =B21-E21 -> 2462.369
A22: ROUGE MP | B22: =+'3010'!H22 -> 1262.53 | D22: KG | F22: 714.82 | G22: =E22*F22 -> 0 | H22: =B22-E22 -> 1262.53
A23: BLANC MP | B23: =+'3010'!H23 -> 230 | D23: KG | F23: 487.38 | G23: =E23*F23 -> 0 | H23: =B23-E23 -> 230
A24: ORANGE MP | B24: =+'3010'!H24 -> 974.652 | D24: KG | F24: 844.79 | G24: =E24*F24 -> 0 | H24: =B24-E24 -> 974.652
A25: VERT MP | B25: =+'3010'!H25 -> 1104 | D25: KG | F25: 901.65 | G25: =E25*F25 -> 0 | H25: =B25-E25 -> 1104
A26: VIOLET MP | B26: =+'3010'!H26 -> 229.04 | D26: KG | F26: 877.28 | G26: =E26*F26 -> 0 | H26: =B26-E26 -> 229.04
A27: VERNICH GLOSS | B27: =+'3010'!H27 -> 969.81 | D27: KG | F27: 300.55 | G27: =E27*F27 -> 0 | H27: =B27-E27 -> 969.81
A28: VERNICH CX3 | B28: =+'3010'!H28 -> 14815.871 | D28: KG | F28: 178.7 | G28: =E28*F28 -> 0 | H28: =B28-E28 -> 14815.871
A29: JAUNE 109 | B29: =+'3010'!H29 -> 19 | D29: KG | G29: =E29*F29 -> 0 | H29: =B29-E29 -> 19
A30: JAUNE 4018 | B30: =+'3010'!H30 -> 0 | D30: KG | G30: =E30*F30 -> 0 | H30: =B30-E30 -> 0
A31: JAUNE PROCESS | B31: =+'3010'!H31 -> 0 | D31: KG | G31: =E31*F31 -> 0 | H31: =B31-E31 -> 0
A32: JAUNE PROCESS C | B32: =+'3010'!H32 -> 40 | D32: KG | G32: =E32*F32 -> 0 | H32: =B32-E32 -> 40
A33: BLEU CYAN | B33: =+'3010'!H33 -> 100 | D33: KG | G33: =E33*F33 -> 0 | H33: =B33-E33 -> 100
A34: BLEU CYAN C | B34: =+'3010'!H34 -> 60 | D34: KG | G34: =E34*F34 -> 0 | H34: =B34-E34 -> 60
A35: BLEU REFLEX | B35: =+'3010'!H35 -> 132 | D35: KG | G35: =E35*F35 -> 0 | H35: =B35-E35 -> 132
A36: BLEU REFLEX COUCHE | B36: =+'3010'!H36 -> 60 | D36: KG | G36: =E36*F36 -> 0 | H36: =B36-E36 -> 60
A37: BLEU 295 C | B37: =+'3010'!H37 -> 0 | D37: KG | G37: =E37*F37 -> 0 | H37: =B37-E37 -> 0
A38: BLEU BADIRA C | B38: =+'3010'!H38 -> 40 | D38: KG | G38: =E38*F38 -> 0 | H38: =B38-E38 -> 40
A39: BLEU BADIRA | B39: =+'3010'!H39 -> 17 | D39: KG | G39: =E39*F39 -> 0 | H39: =B39-E39 -> 17
A40: BLEU 2765 C | B40: =+'3010'!H40 -> 40 | D40: KG | G40: =E40*F40 -> 0 | H40: =B40-E40 -> 40
... A71: P200 | B71: =+'3010'!H71 -> 40 | D71: KG | G71: =E71*F71 -> 0 | H71: =B71-E71 -> 40
...

Sheet 0211
A2: DESCRIPTION | B2: 45963
B3: STOCK INT | C3: RECEPTION | D3: UNITE | E3: SORTIER | F3: PRIX | G3: VALEUR | H3: STOCK
A4: DOUBLE FACE | B4: =+'0111'!H4 -> 32 | D4: ROULEAU | E4: 5 | F4: 230.62 | G4: =E4*F4 -> 1153.1 | H4: =B4-E4 -> 27
A5: SCOTCHE | B5: =+'0111'!H5 -> 61 | D5: ROULEAU | E5: 1 | F5: 91.2 | G5: =E5*F5 -> 91.2 | H5: =B5-E5 -> 60
A6: FEUILLARD N12 | B6: =+'0111'!H6 -> 216 | D6: ROULEAU | E6: 3 | F6: 3500 | G6: =E6*F6 -> 10500 | H6: =B6-E6 -> 213
A7: FEUILLARD N5 | B7: =+'0111'!H7 -> 11 | D7: ROULEAU | F7: 3300 | G7: =E7*F7 -> 0 | H7: =B7-E7 -> 11
A8: CELOPHANE 7 | B8: =+'0111'!H8 -> 48 | D8: ROULEAU | F8: 1554.62 | G8: =E8*F8 -> 0 | H8: =B8-E8 -> 48
A9: CELOPHANE 16 | B9: =+'0111'!H9 -> 2316 | D9: KG | E9: 48 | F9: 210 | G9: =E9*F9 -> 10080 | H9: =B9-E9 -> 2268
A10: CELOPHANE 25 | B10: =+'0111'!H10 -> 24 | D10: KG | G10: =E10*F10 -> 0 | H10: =B10-E10 -> 24
A11: COLLE | B11: =+'0111'!H11 -> 1110 | D11: KG | F11: 290 | G11: =E11*F11 -> 0 | H11: =B11-E11 -> 1110
A12: SEL | B12: =+'0111'!H12 -> 2725 | D12: KG | E12: =4*25 -> 100 | F12: 49.5 | G12: =E12*F12 -> 4950 | H12: =B12-E12 -> 2625
A13: BORAX | B13: =+'0111'!H13 -> 400 | D13: KG | E13: =3*25 -> 75 | F13: 285 | G13: =E13*F13 -> 21375 | H13: =B13-E13 -> 325
A14: AMIDON | B14: =+'0111'!H14 -> 56775 | D14: KG | E14: =56*25 -> 1400 | F14: 93 | G14: =E14*F14 -> 130200 | H14: =B14-E14 -> 55375
A15: SOUDE | B15: =+'0111'!H15 -> 2132 | D15: KG | E15: 60 | F15: 67.23 | G15: =E15*F15 -> 4033.8 | H15: =B15-E15 -> 2072
A16: ANALYFLIX | B16: =+'0111'!H16 -> 325 | D16: KG | F16: 480 | G16: =E16*F16 -> 0 | H16: =B16-E16 -> 325
A17: FIL RECUIT | B17: =+'0111'!H17 -> 26 | D17: ROULEAU | G17: =E17*F17 -> 0 | H17: =B17-E17 -> 26
A18: JAUNE MP | B18: =+'0111'!H18 -> 1534.693 | D18: KG | F18: 877.28 | G18: =E18*F18 -> 0 | H18: =B18-E18 -> 1534.693
A19: BLUE MP | B19: =+'0111'!H19 -> 344.971 | D19: KG | F19: 601.1 | G19: =E19*F19 -> 0 | H19: =B19-E19 -> 344.971
A20: MAGENTA MP | B20: =+'0111'!H20 -> 990.22 | D20: KG | F20: 568.61 | G20: =E20*F20 -> 0 | H20: =B20-E20 -> 990.22
A21: NOIR MP | B21: =+'0111'!H21 -> 2462.369 | D21: KG | F21: 333.04 | G21: =E21*F21 -> 0 | H21: =B21-E21 -> 2462.369
A22: ROUGE MP | B22: =+'0111'!H22 -> 1262.53 | D22: KG | F22: 714.82 | G22: =E22*F22 -> 0 | H22: =B22-E22 -> 1262.53
A23: BLANC MP | B23: =+'0111'!H23 -> 230 | D23: KG | F23: 487.38 | G23: =E23*F23 -> 0 | H23: =B23-E23 -> 230
A24: ORANGE MP | B24: =+'0111'!H24 -> 974.652 | D24: KG | F24: 844.79 | G24: =E24*F24 -> 0 | H24: =B24-E24 -> 974.652
A25: VERT MP | B25: =+'0111'!H25 -> 1104 | D25: KG | F25: 901.65 | G25: =E25*F25 -> 0 | H25: =B25-E25 -> 1104
A26: VIOLET MP | B26: =+'0111'!H26 -> 229.04 | D26: KG | F26: 877.28 | G26: =E26*F26 -> 0 | H26: =B26-E26 -> 229.04
A27: VERNICH GLOSS | B27: =+'0111'!H27 -> 969.81 | D27: KG | F27: 300.55 | G27: =E27*F27 -> 0 | H27: =B27-E27 -> 969.81
A28: VERNICH CX3 | B28: =+'0111'!H28 -> 14815.871 | D28: KG | F28: 178.7 | G28: =E28*F28 -> 0 | H28: =B28-E28 -> 14815.871
A29: JAUNE 109 | B29: =+'0111'!H29 -> 19 | D29: KG | G29: =E29*F29 -> 0 | H29: =B29-E29 -> 19
A30: JAUNE 4018 | B30: =+'0111'!H30 -> 0 | D30: KG | G30: =E30*F30 -> 0 | H30: =B30-E30 -> 0
A31: JAUNE PROCESS | B31: =+'0111'!H31 -> 0 | D31: KG | G31: =E31*F31 -> 0 | H31: =B31-E31 -> 0
A32: JAUNE PROCESS C | B32: =+'0111'!H32 -> 40 | D32: KG | G32: =E32*F32 -> 0 | H32: =B32-E32 -> 40
A33: BLEU CYAN | B33: =+'0111'!H33 -> 100 | D33: KG | G33: =E33*F33 -> 0 | H33: =B33-E33 -> 100
A34: BLEU CYAN C | B34: =+'0111'!H34 -> 60 | D34: KG | G34: =E34*F34 -> 0 | H34: =B34-E34 -> 60
A35: BLEU REFLEX | B35: =+'0111'!H35 -> 132 | D35: KG | E35: 17 | G35: =E35*F35 -> 0 | H35: =B35-E35 -> 115
A36: BLEU REFLEX COUCHE | B36: =+'0111'!H36 -> 60 | D36: KG | G36: =E36*F36 -> 0 | H36: =B36-E36 -> 60
A37: BLEU 295 C | B37: =+'0111'!H37 -> 0 | D37: KG | G37: =E37*F37 -> 0 | H37: =B37-E37 -> 0
A38: BLEU BADIRA C | B38: =+'0111'!H38 -> 40 | D38: KG | G38: =E38*F38 -> 0 | H38: =B38-E38 -> 40
A39: BLEU BADIRA | B39: =+'0111'!H39 -> 17 | D39: KG | G39: =E39*F39 -> 0 | H39: =B39-E39 -> 17
A40: BLEU 2765 C | B40: =+'0111'!H40 -> 40 | D40: KG | G40: =E40*F40 -> 0 | H40: =B40-E40 -> 40
A41: BLEU 3557 | B41: =+'0111'!H41 -> 60 | D41: KG | G41: =E41*F41 -> 0 | H41: =B41-E41 -> 60
...

Sheet 0311
A2: DESCRIPTION | B2: 45964
B3: STOCK INT | C3: RECEPTION | D3: UNITE | E3: SORTIER | F3: PRIX | G3: VALEUR | H3: STOCK
A4: DOUBLE FACE | B4: =+'0211'!H4 -> 27 | D4: ROULEAU | E4: 3 | F4: 230.62 | G4: =E4*F4 -> 691.86 | H4: =B4-E4 -> 24
A5: SCOTCHE | B5: =+'0211'!H5 -> 60 | D5: ROULEAU | E5: 2 | F5: 91.2 | G5: =E5*F5 -> 182.4 | H5: =B5-E5 -> 58
A6: FEUILLARD N12 | B6: =+'0211'!H6 -> 213 | D6: ROULEAU | E6: 2 | F6: 3500 | G6: =E6*F6 -> 7000 | H6: =B6-E6 -> 211
A7: FEUILLARD N5 | B7: =+'0211'!H7 -> 11 | D7: ROULEAU | F7: 3300 | G7: =E7*F7 -> 0 | H7: =B7-E7 -> 11
A8: CELOPHANE 7 | B8: =+'0211'!H8 -> 48 | D8: ROULEAU | F8: 1554.62 | G8: =E8*F8 -> 0 | H8: =B8-E8 -> 48
A9: CELOPHANE 16 | B9: =+'0211'!H9 -> 2268 | D9: KG | E9: 32 | F9: 210 | G9: =E9*F9 -> 6720 | H9: =B9-E9 -> 2236
A10: CELOPHANE 25 | B10: =+'0211'!H10 -> 24 | D10: KG | G10: =E10*F10 -> 0 | H10: =B10-E10 -> 24
A11: COLLE | B11: =+'0211'!H11 -> 1110 | D11: KG | E11: 60 | F11: 290 | G11: =E11*F11 -> 17400 | H11: =B11-E11 -> 1050
A12: SEL | B12: =+'0211'!H12 -> 2625 | D12: KG | F12: 49.5 | G12: =E12*F12 -> 0 | H12: =B12-E12 -> 2625
A13: BORAX | B13: =+'0211'!H13 -> 325 | D13: KG | F13: 285 | G13: =E13*F13 -> 0 | H13: =B13-E13 -> 325
A14: AMIDON | B14: =+'0211'!H14 -> 55375 | D14: KG | E14: =32*25 -> 800 | F14: 93 | G14: =E14*F14 -> 74400 | H14: =B14-E14 -> 54575
A15: SOUDE | B15: =+'0211'!H15 -> 2072 | D15: KG | E15: 70 | F15: 67.23 | G15: =E15*F15 -> 4706.1 | H15: =B15-E15 -> 2002
A16: ANALYFLIX | B16: =+'0211'!H16 -> 325 | D16: KG | F16: 480 | G16: =E16*F16 -> 0 | H16: =B16-E16 -> 325
A17: FIL RECUIT | B17: =+'0211'!H17 -> 26 | D17: ROULEAU | G17: =E17*F17 -> 0 | H17: =B17-E17 -> 26
A18: JAUNE MP | B18: =+'0211'!H18 -> 1534.693 | D18: KG | E18: 6.78 | F18: 877.28 | G18: =E18*F18 -> 5947.9584 | H18: =B18-E18 -> 1527.913
A19: BLUE MP | B19: =+'0211'!H19 -> 344.971 | D19: KG | F19: 601.1 | G19: =E19*F19 -> 0 | H19: =B19-E19 -> 344.971
A20: MAGENTA MP | B20: =+'0211'!H20 -> 990.22 | D20: KG | F20: 568.61 | G20: =E20*F20 -> 0 | H20: =B20-E20 -> 990.22
A21: NOIR MP | B21: =+'0211'!H21 -> 2462.369 | D21: KG | F21: 333.04 | G21: =E21*F21 -> 0 | H21: =B21-E21 -> 2462.369
A22: ROUGE MP | B22: =+'0211'!H22 -> 1262.53 | D22: KG | F22: 714.82 | G22: =E22*F22 -> 0 | H22: =B22-E22 -> 1262.53
A23: BLANC MP | B23: =+'0211'!H23 -> 230 | D23: KG | F23: 487.38 | G23: =E23*F23 -> 0 | H23: =B23-E23 -> 230
A24: ORANGE MP | B24: =+'0211'!H24 -> 974.652 | D24: KG | E24: =0.578 -> 0.578 | F24: 844.79 | G24: =E24*F24 -> 488.28862 | H24: =B24-E24 -> 974.074
A25: VERT MP | B25: =+'0211'!H25 -> 1104 | D25: KG | F25: 901.65 | G25: =E25*F25 -> 0 | H25: =B25-E25 -> 1104
A26: VIOLET MP | B26: =+'0211'!H26 -> 229.04 | D26: KG | F26: 877.28 | G26: =E26*F26 -> 0 | H26: =B26-E26 -> 229.04
A27: VERNICH GLOSS | B27: =+'0211'!H27 -> 969.81 | D27: KG | F27: 300.55 | G27: =E27*F27 -> 0 | H27: =B27-E27 -> 969.81
A28: VERNICH CX3 | B28: =+'0211'!H28 -> 14815.871 | D28: KG | E28: =6.235 -> 6.235 | F28: 178.7 | G28: =E28*F28 -> 1114.1945 | H28: =B28-E28 -> 14809.636
A29: JAUNE 109 | B29: =+'0211'!H29 -> 19 | D29: KG | G29: =E29*F29 -> 0 | H29: =B29-E29 -> 19
A30: JAUNE 4018 | B30: =+'0211'!H30 -> 0 | D30: KG | G30: =E30*F30 -> 0 | H30: =B30-E30 -> 0
A31: JAUNE PROCESS | B31: =+'0211'!H31 -> 0 | D31: KG | G31: =E31*F31 -> 0 | H31: =B31-E31 -> 0
A32: JAUNE PROCESS C | B32: =+'0211'!H32 -> 40 | D32: KG | G32: =E32*F32 -> 0 | H32: =B32-E32 -> 40
A33: BLEU CYAN | B33: =+'0211'!H33 -> 100 | D33: KG | G33: =E33*F33 -> 0 | H33: =B33-E33 -> 100
A34: BLEU CYAN C | B34: =+'0211'!H34 -> 60 | D34: KG | G34: =E34*F34 -> 0 | H34: =B34-E34 -> 60
A35: BLEU REFLEX | B35: =+'0211'!H35 -> 115 | D35: KG | G35: =E35*F35 -> 0 | H35: =B35-E35 -> 115
A36: BLEU REFLEX COUCHE | B36: =+'0211'!H36 -> 60 | D36: KG | G36: =E36*F36 -> 0 | H36: =B36-E36 -> 60
A37: BLEU 295 C | B37: =+'0211'!H37 -> 0 | D37: KG | G37: =E37*F37 -> 0 | H37: =B37-E37 -> 0
A38: BLEU BADIRA C | B38: =+'0211'!H38 -> 40 | D38: KG | G38: =E38*F38 -> 0 | H38: =B38-E38 -> 40
A39: BLEU BADIRA | B39: =+'0211'!H39 -> 17 | D39: KG | G39: =E39*F39 -> 0 | H39: =B39-E39 -> 17
A40: BLEU 2765 C | B40: =+'0211'!H40 -> 40 | D40: KG | G40: =E40*F40 -> 0 | H40: =B40-E40 -> 40
... A46: MARRON 7502 | B46: =+'0211'!H46 -> 100 | D46: KG | G46: =E46*F46 -> 0 | H46: =B46-E46 -> 100
...

Sheet 0411
A2: DESCRIPTION | B2: 45965
B3: STOCK INT | C3: RECEPTION | D3: UNITE | E3: SORTIER | F3: PRIX | G3: VALEUR | H3: STOCK
A4: DOUBLE FACE | B4: =+'0311'!H4 -> 24 | C4: 158 | D4: ROULEAU | E4: 4 | F4: 230.62 | G4: =E4*F4 -> 922.48 | H4: =B4-E4+C4 -> 178
A5: SCOTCHE | B5: =+'0311'!H5 -> 58 | D5: ROULEAU | F5: 91.2 | G5: =E5*F5 -> 0 | H5: =B5-E5 -> 58
A6: FEUILLARD N12 | B6: =+'0311'!H6 -> 211 | D6: ROULEAU | E6: 2 | F6: 3500 | G6: =E6*F6 -> 7000 | H6: =B6-E6 -> 209
A7: FEUILLARD N5 | B7: =+'0311'!H7 -> 11 | C7: 50 | D7: ROULEAU | E7: 2 | F7: 3300 | G7: =E7*F7 -> 6600 | H7: =B7-E7+C7 -> 59
A8: CELOPHANE 7 | B8: =+'0311'!H8 -> 48 | D8: ROULEAU | E8: 3 | F8: 1554.62 | G8: =E8*F8 -> 4663.86 | H8: =B8-E8 -> 45
A9: CELOPHANE 16 | B9: =+'0311'!H9 -> 2236 | D9: KG | E9: 48 | F9: 210 | G9: =E9*F9 -> 10080 | H9: =B9-E9 -> 2188
A10: CELOPHANE 25 | B10: =+'0311'!H10 -> 24 | D10: KG | G10: =E10*F10 -> 0 | H10: =B10-E10 -> 24
A11: COLLE | B11: =+'0311'!H11 -> 1050 | D11: KG | E11: 30 | F11: 290 | G11: =E11*F11 -> 8700 | H11: =B11-E11 -> 1020
A12: SEL | B12: =+'0311'!H12 -> 2625 | D12: KG | E12: 50 | F12: 49.5 | G12: =E12*F12 -> 2475 | H12: =B12-E12 -> 2575
A13: BORAX | B13: =+'0311'!H13 -> 325 | D13: KG | F13: 285 | G13: =E13*F13 -> 0 | H13: =B13-E13 -> 325
A14: AMIDON | B14: =+'0311'!H14 -> 54575 | D14: KG | E14: =30*25 -> 750 | F14: 93 | G14: =E14*F14 -> 69750 | H14: =B14-E14 -> 53825
A15: SOUDE | B15: =+'0311'!H15 -> 2002 | D15: KG | E15: 56 | F15: 67.23 | G15: =E15*F15 -> 3764.88 | H15: =B15-E15 -> 1946
A16: ANALYFLIX | B16: =+'0311'!H16 -> 325 | D16: KG | F16: 480 | G16: =E16*F16 -> 0 | H16: =B16-E16 -> 325
A17: FIL RECUIT | B17: =+'0311'!H17 -> 26 | D17: ROULEAU | G17: =E17*F17 -> 0 | H17: =B17-E17 -> 26
A18: JAUNE MP | B18: =+'0311'!H18 -> 1527.913 | D18: KG | F18: 877.28 | G18: =E18*F18 -> 0 | H18: =B18-E18 -> 1527.913
A19: BLUE MP | B19: =+'0311'!H19 -> 344.971 | D19: KG | F19: 601.1 | G19: =E19*F19 -> 0 | H19: =B19-E19 -> 344.971
A20: MAGENTA MP | B20: =+'0311'!H20 -> 990.22 | D20: KG | F20: 568.61 | G20: =E20*F20 -> 0 | H20: =B20-E20 -> 990.22
A21: NOIR MP | B21: =+'0311'!H21 -> 2462.369 | D21: KG | F21: 333.04 | G21: =E21*F21 -> 0 | H21: =B21-E21 -> 2462.369
A22: ROUGE MP | B22: =+'0311'!H22 -> 1262.53 | D22: KG | F22: 714.82 | G22: =E22*F22 -> 0 | H22: =B22-E22 -> 1262.53
A23: BLANC MP | B23: =+'0311'!H23 -> 230 | D23: KG | F23: 487.38 | G23: =E23*F23 -> 0 | H23: =B23-E23 -> 230
A24: ORANGE MP | B24: =+'0311'!H24 -> 974.074 | D24: KG | F24: 844.79 | G24: =E24*F24 -> 0 | H24: =B24-E24 -> 974.074
A25: VERT MP | B25: =+'0311'!H25 -> 1104 | D25: KG | F25: 901.65 | G25: =E25*F25 -> 0 | H25: =B25-E25 -> 1104
A26: VIOLET MP | B26: =+'0311'!H26 -> 229.04 | D26: KG | F26: 877.28 | G26: =E26*F26 -> 0 | H26: =B26-E26 -> 229.04
A27: VERNICH GLOSS | B27: =+'0311'!H27 -> 969.81 | D27: KG | F27: 300.55 | G27: =E27*F27 -> 0 | H27: =B27-E27 -> 969.81
A28: VERNICH CX3 | B28: =+'0311'!H28 -> 14809.636 | D28: KG | F28: 178.7 | G28: =E28*F28 -> 0 | H28: =B28-E28 -> 14809.636
A29: JAUNE 109 | B29: =+'0311'!H29 -> 19 | D29: KG | G29: =E29*F29 -> 0 | H29: =B29-E29 -> 19
A30: JAUNE 4018 | B30: =+'0311'!H30 -> 0 | D30: KG | G30: =E30*F30 -> 0 | H30: =B30-E30 -> 0
A31: JAUNE PROCESS | B31: =+'0311'!H31 -> 0 | D31: KG | G31: =E31*F31 -> 0 | H31: =B31-E31 -> 0
A32: JAUNE PROCESS C | B32: =+'0311'!H32 -> 40 | D32: KG | G32: =E32*F32 -> 0 | H32: =B32-E32 -> 40
A33: BLEU CYAN | B33: =+'0311'!H33 -> 100 | D33: KG | G33: =E33*F33 -> 0 | H33: =B33-E33 -> 100
A34: BLEU CYAN C | B34: =+'0311'!H34 -> 60 | D34: KG | G34: =E34*F34 -> 0 | H34: =B34-E34 -> 60
A35: BLEU REFLEX | B35: =+'0311'!H35 -> 115 | D35: KG | G35: =E35*F35 -> 0 | H35: =B35-E35 -> 115
A36: BLEU REFLEX COUCHE | B36: =+'0311'!H36 -> 60 | D36: KG | G36: =E36*F36 -> 0 | H36: =B36-E36 -> 60
A37: BLEU 295 C | B37: =+'0311'!H37 -> 0 | D37: KG | G37: =E37*F37 -> 0 | H37: =B37-E37 -> 0
A38: BLEU BADIRA C | B38: =+'0311'!H38 -> 40 | D38: KG | G38: =E38*F38 -> 0 | H38: =B38-E38 -> 40
A39: BLEU BADIRA | B39: =+'0311'!H39 -> 17 | D39: KG | G39: =E39*F39 -> 0 | H39: =B39-E39 -> 17
A40: BLEU 2765 C | B40: =+'0311'!H40 -> 40 | D40: KG | G40: =E40*F40 -> 0 | H40: =B40-E40 -> 40
... A72: PONTON 137 | B72: =+'0311'!H72 -> 15 | D72: KG | G72: =E72*F72 -> 0 | H72: =B72-E72 -> 15
...

Sheet 0511
A2: DESCRIPTION | B2: 45966
B3: STOCK INT | C3: RECEPTION | D3: UNITE | E3: SORTIER | F3: PRIX | G3: VALEUR | H3: STOCK
A4: DOUBLE FACE | B4: =+'0411'!H4 -> 178 | C4: 158 | D4: ROULEAU | E4: 6 | F4: 230.62 | G4: =E4*F4 -> 1383.72 | H4: =B4-E4 -> 172
A5: SCOTCHE | B5: =+'0411'!H5 -> 58 | C5: 53 | D5: ROULEAU | E5: 6 | F5: 91.2 | G5: =E5*F5 -> 547.2 | H5: =B5-E5+C5 -> 105
A6: FEUILLARD N12 | B6: =+'0411'!H6 -> 209 | D6: ROULEAU | E6: 1 | F6: 3500 | G6: =E6*F6 -> 3500 | H6: =B6-E6 -> 208
A7: FEUILLARD N5 | B7: =+'0411'!H7 -> 59 | C7: 50 | D7: ROULEAU | F7: 3300 | G7: =E7*F7 -> 0 | H7: =B7-E7 -> 59
A8: CELOPHANE 7 | B8: =+'0411'!H8 -> 45 | D8: ROULEAU | F8: 1554.62 | G8: =E8*F8 -> 0 | H8: =B8-E8 -> 45
A9: CELOPHANE 16 | B9: =+'0411'!H9 -> 2188 | D9: KG | E9: 32 | F9: 210 | G9: =E9*F9 -> 6720 | H9: =B9-E9 -> 2156
A10: CELOPHANE 25 | B10: =+'0411'!H10 -> 24 | D10: KG | G10: =E10*F10 -> 0 | H10: =B10-E10 -> 24
A11: COLLE | B11: =+'0411'!H11 -> 1020 | D11: KG | F11: 290 | G11: =E11*F11 -> 0 | H11: =B11-E11 -> 1020
A12: SEL | B12: =+'0411'!H12 -> 2575 | D12: KG | F12: 49.5 | G12: =E12*F12 -> 0 | H12: =B12-E12 -> 2575
A13: BORAX | B13: =+'0411'!H13 -> 325 | D13: KG | F13: 285 | G13: =E13*F13 -> 0 | H13: =B13-E13 -> 325
A14: AMIDON | B14: =+'0411'!H14 -> 53825 | D14: KG | E14: =52*25 -> 1300 | F14: 93 | G14: =E14*F14 -> 120900 | H14: =B14-E14 -> 52525
A15: SOUDE | B15: =+'0411'!H15 -> 1946 | D15: KG | E15: 70 | F15: 67.23 | G15: =E15*F15 -> 4706.1 | H15: =B15-E15 -> 1876
A16: ANALYFLIX | B16: =+'0411'!H16 -> 325 | D16: KG | F16: 480 | G16: =E16*F16 -> 0 | H16: =B16-E16 -> 325
A17: FIL RECUIT | B17: =+'0411'!H17 -> 26 | D17: ROULEAU | G17: =E17*F17 -> 0 | H17: =B17-E17 -> 26
A18: JAUNE MP | B18: =+'0411'!H18 -> 1527.913 | D18: KG | E18: =33.8 -> 33.8 | F18: 877.28 | G18: =E18*F18 -> 29652.064 | H18: =B18-E18 -> 1494.113
A19: BLUE MP | B19: =+'0411'!H19 -> 344.971 | D19: KG | F19: 601.1 | G19: =E19*F19 -> 0 | H19: =B19-E19 -> 344.971
A20: MAGENTA MP | B20: =+'0411'!H20 -> 990.22 | D20: KG | E20: 39.67 | F20: 568.61 | G20: =E20*F20 -> 22556.759 | H20: =B20-E20 -> 950.55
A21: NOIR MP | B21: =+'0411'!H21 -> 2462.369 | D21: KG | E21: 0.5 | F21: 333.04 | G21: =E21*F21 -> 166.52 | H21: =B21-E21 -> 2461.869
A22: ROUGE MP | B22: =+'0411'!H22 -> 1262.53 | D22: KG | E22: 1.45 | F22: 714.82 | G22: =E22*F22 -> 1036.489 | H22: =B22-E22 -> 1261.08
A23: BLANC MP | B23: =+'0411'!H23 -> 230 | D23: KG | E23: 72 | F23: 487.38 | G23: =E23*F23 -> 35091.36 | H23: =B23-E23 -> 158
A24: ORANGE MP | B24: =+'0411'!H24 -> 974.074 | D24: KG | E24: 0.25 | F24: 844.79 | G24: =E24*F24 -> 211.1975 | H24: =B24-E24 -> 973.824
A25: VERT MP | B25: =+'0411'!H25 -> 1104 | D25: KG | E25: 0.7 | F25: 901.65 | G25: =E25*F25 -> 631.155 | H25: =B25-E25 -> 1103.3
A26: VIOLET MP | B26: =+'0411'!H26 -> 229.04 | D26: KG | E26: 4 | F26: 877.28 | G26: =E26*F26 -> 3509.12 | H26: =B26-E26 -> 225.04
A27: VERNICH GLOSS | B27: =+'0411'!H27 -> 969.81 | D27: KG | E27: 73.2 | F27: 300.55 | G27: =E27*F27 -> 22000.26 | H27: =B27-E27 -> 896.61
A28: VERNICH CX3 | B28: =+'0411'!H28 -> 14809.636 | D28: KG | E28: 56 | F28: 178.7 | G28: =E28*F28 -> 10007.2 | H28: =B28-E28 -> 14753.636
A29: JAUNE 109 | B29: =+'0411'!H29 -> 19 | C29: =34 -> 34 | D29: KG | E29: 17 | G29: =E29*F29 -> 0 | H29: =B29-E29+C29 -> 36
A30: JAUNE 4020 | B30: =+'0411'!H30 -> 0 | C30: 88 | D30: KG | E30: 88 | G30: =E30*F30 -> 0 | H30: =B30-E30+C30 -> 0
A31: JAUNE PROCESS | B31: =+'0411'!H31 -> 0 | D31: KG | G31: =E31*F31 -> 0 | H31: =B31-E31 -> 0
A32: JAUNE PROCESS C | B32: =+'0411'!H32 -> 40 | D32: KG | G32: =E32*F32 -> 0 | H32: =B32-E32 -> 40
A33: BLEU CYAN | B33: =+'0411'!H33 -> 100 | D33: KG | G33: =E33*F33 -> 0 | H33: =B33-E33 -> 100
A34: BLEU CYAN C | B34: =+'0411'!H34 -> 60 | D34: KG | G34: =E34*F34 -> 0 | H34: =B34-E34 -> 60
A35: BLEU REFLEX | B35: =+'0411'!H35 -> 115 | D35: KG | G35: =E35*F35 -> 0 | H35: =B35-E35 -> 115
A36: BLEU REFLEX COUCHE | B36: =+'0411'!H36 -> 60 | D36: KG | G36: =E36*F36 -> 0 | H36: =B36-E36 -> 60
A37: BLEU 295 C | B37: =+'0411'!H37 -> 0 | D37: KG | G37: =E37*F37 -> 0 | H37: =B37-E37 -> 0
A38: BLEU BADIRA C | B38: =+'0411'!H38 -> 40 | D38: KG | G38: =E38*F38 -> 0 | H38: =B38-E38 -> 40
A39: BLEU BADIRA | B39: =+'0411'!H39 -> 17 | D39: KG | G39: =E39*F39 -> 0 | H39: =B39-E39 -> 17
A40: BLEU 2765 C | B40: =+'0411'!H40 -> 40 | D40: KG | G40: =E40*F40 -> 0 | H40: =B40-E40 -> 40
